Workbook

Sheet LIST_DX
B2: ■ 디스커버리 26FW 상품속성 (DJ기준)
B3: {=_xlfn.UNIQUE('RAW_DX(DJ)'!M:M)} -> 0 | C3: {=_xlfn.UNIQUE('RAW_DX(DJ)'!N:N)} -> 0 | D3: {=_xlfn.UNIQUE('RAW_DX(DJ)'!O:O)} -> 0 | E3: {=_xlfn.UNIQUE('RAW_DX(DJ)'!P:P)} -> 0 | F3: {=_xlfn.UNIQUE('RAW_DX(DJ)'!Q:Q)} -> 0 | G3: {=_xlfn.UNIQUE('RAW_DX(DJ)'!R:R)} -> 0 | H3: {=_xlfn.UNIQUE('RAW_DX(DJ)'!S:S)} -> 0 | I3: {=_xlfn.UNIQUE('RAW_DX(DJ)'!T:T)} -> 0 | J3: {=_xlfn.UNIQUE('RAW_DX(DJ)'!U:U)} -> 0 | K3: {=_xlfn.UNIQUE('RAW_DX(DJ)'!V:V)} -> 0 | L3: {=_xlfn.UNIQUE('RAW_DX(DJ)'!W:W)} -> 0 | M3: {=_xlfn.UNIQUE('RAW_DX(DJ)'!X:X)} -> 0 | N3: {=_xlfn.UNIQUE('RAW_DX(DJ)'!Y:Y)} -> 0 | O3: {=_xlfn.UNIQUE('RAW_DX(DJ)'!Z:Z)} -> 0 | P3: {=_xlfn.UNIQUE('RAW_DX(DJ)'!AA:AA)} -> 0 | Q3: {=_xlfn.UNIQUE('RAW_DX(DJ)'!AB:AB)} -> 0 | R3: {=_xlfn.UNIQUE('RAW_DX(DJ)'!AC:AC)} -> 0 | S3: {=_xlfn.UNIQUE('RAW_DX(DJ)'!AD:AD)} -> 0 | T3: {=_xlfn.UNIQUE('RAW_DX(DJ)'!AE:AE)} -> 0 | U3: {=_xlfn.UNIQUE('RAW_DX(DJ)'!AF:AF)} -> 0 | V3: {=_xlfn.UNIQUE('RAW_DX(DJ)'!AG:AG)} -> 0 | W3: {=_xlfn.UNIQUE('RAW_DX(DJ)'!AH:AH)} -> 0 | X3: {=_xlfn.UNIQUE('RAW_DX(DJ)'!AI:AI)} -> 0 | Y3: {=_xlfn.UNIQUE('RAW_DX(DJ)'!AJ:AJ)} -> 0
B4: ▶소재 스팩 정보 | C4: 소재명 | D4: 소재 혼용율 | E4: 소재 혼용율% | F4: 원사 데니아(D) | G4: 소재 중량(G) | H4: 소재 밀도(T) | I4: 레이어(필름) | J4: 레이어(필름) 두께 | K4: 소재 후가공 | L4: 소재 TAG | M4: ▶소재 외관 정보 | N4: 소재 조직 | O4: Ra값 (Roughness Average) | P4: GU값 (Gloss Units) | Q4: ▶다운백 정보 | R4: 다운백 데니아(D) | S4: 다운백 밀도(T) | T4: ▶충전재 정보 | U4: 충전재양(G) | V4: 중량 구분 | W4: 필파워 | X4: ▶디자인 정보 | Y4: 기장
B5: 소재처 | C5: CAC-CN6811 2T | D5: NYLON | E5: 100 | F5: 20D | G5: 40G | H5: 400T | I5: Single L | J5: 7mic | K5: CIRE | L5: PERTEX | M5: 소재 구분 | N5: PLAIN | O5: 소재 텍스쳐(Ra) LEVEL | P5: 소재 광택(GU) LEVEL | Q5: 다운백 구조 | R5: 20D | S5: 400T | T5: 충전재 사종 | U5: 110G | V5: 중량 | W5: 650 | X5: 디자인 형태 | Y5: 크롭
B6: C&A | C6: PN-3972S-5 | D6: POLYESTER/POLYURETHANE | E6: 90/10 | F6: 30D | G6: 165G | H6: 443T | I6: 2L | J6: 8mic | K6: WR | L6: GORE-TEX | M6: 우븐 | N6: TUBE | O6: Ra_LV1 | P6: GU_LV5 | Q6: 4L 구조 | R6: (다운백 없음) | S6: (다운백 없음) | T6: EU DUCK 8020 | U6: 60G | V6: 경량 | W6: 700 | X6: 중량패딩 | Y6: 스탠다드
B7: 영보 | C7: PF-23032-12 (P30D 사각 튜브) 12CM | D7: POLYESTER | E7: 95/5 | F7: 50D | G7: 135G | H7: 442T | I7: 3L | J7: 20mic | K7: WR, CIRE | L7: BERTEX | M7: 니트 | N7: RIPSTOP | O7: Ra_LV2 | P7: GU_LV2 | Q7: 2L 구조(튜브) | R7: 30D | S7: 360T | T7: EU GOOSE 8020 | U7: 165G | V7: 헤비 | X7: 경량패딩 | Y7: 세미크롭
B8: 원창 | C8: PF-23032-12C (12CM사각_cire) | D8: POLYURETHANE | E8: 88/12 | F8: 10D | G8: 70G | H8: 239T | J8: 30mic | K8: DWR | N8: CODUROY | O8: Ra_LV4 | P8: GU_LV4 | Q8: 2L 구조 | R8: 40D | S8: 320T | T8: SynCloud Ball Insulation | U8: 140G | X8: 크롭패딩 | Y8: 미드
B9: 플레이트 | C9: CVST230218C-01 | D9: NYLON/POLYURETHANE | F9: 75D | G9: 44G | H9: 290T | J9: 15mic | K9: DWR,CIRE | N9: BOA | O9: Ra_LV5 | P9: GU_LV3 | Q9: 3L 구조 | R9: 15D | T9: EU DUCK 9010 | U9: 180G | X9: 미드패딩 | Y9: 슈퍼크롭
B10: 26STORY | C10: PS-1286 | D10: POLYESTER | F10: 15D | G10: 160G | H10: 505T | J10: 10mic | K10: WR,CIRE | N10: TWILL | O10: Ra_LV3 | T10: EU GOOSE 9010 | U10: 170G | X10: 롱패딩 | Y10: 롱
B11: BKT | C11: 26-BELLINA-1003 | F11: 70D | G11: 77G | H11: 300T | J11: 6mic | N11: DOBBY | U11: 130G | X11: 숏패딩
B12: TOPTEX | C12: BKW-WMS-028 | F12: 25D | G12: 39G | H12: (니트소재 밀도 없음) | U12: 150G | X12: 패딩베스트
B13: KOA | C13: N2040CT | F13: 40D | G13: 29G | H13: 441T | U13: 160G
B14: SPM | C14: CAC-KM0023 | G14: 97G | H14: 203T | U14: 210G
B15: 네오드림 | C15: BKW-WMS-603 | G15: 225G | H15: 477T | U15: 242G
B16: 신한 | C16: KA2508-01C | G16: 370G | H16: 491T | U16: 133G
B17: PERTEX | C17: ACNE_DT 15 | G17: 90G | H17: 305T | U17: 85G
B18: GORE | C18: NEO-226F128 | G18: 26G | H18: 210T | U18: 115G
B19: MOVE | C19: SH-FP1440 DC | G19: 38G | H19: 413T | U19: 90G
B20: 덕성 | C20: GD-210C | G20: 172G | H20: 320T | U20: 240G
B21: FLOWTEX | C21: SL-1417CT | G21: 100G | H21: 398T | U21: 195G
B22: KIS | C22: PRD812-NFC | G22: 120G | H22: 218T | U22: 290G
B23: 라임 | C23: GL-151C | G23: 53G | H23: 444T | U23: 220G
B24: 해원 | C24: BNRSPL75ES-PX 2L | G24: 108G | H24: 499T | U24: 320G
B25: 봄텍스 | C25: TFCT-9039 (3K/3K 2L) | G25: 75G | H25: 435T | U25: 175G
... B30: MD글로벌 | C30: PF-24028M (지그재그 9.5*9.5) | G30: 45G | H30: 240T | U30: 106G
C31: PF-24028W (지그재그 튜브 9 * 9) | G31: 102G | H31: 209T | U31: 135G
C32: SOLID PU-1002 | G32: 58G | H32: 232T | U32: 105G
C33: CJP-430P-ST | G33: 55G | H33: 310T | U33: 95G
C34: D1417-34C20 | G34: 52G | H34: 220T | U34: 75G
C35: KP-4039 | G35: 68G | H35: 376T | U35: 265G
C36: MC-2572 FC | G36: 84G | H36: 482T | U36: 215G
C37: TP00-0343 | G37: 95G | H37: 370T | U37: 232G
C38: LS-7243 | G38: 125G | H38: 219T | U38: 182G
C39: BKW-WMS-421 | G39: 192G | H39: 380T | U39: 355G
C40: NEO-K26F19 | G40: 54G | H40: 327T | U40: 275G
C41: HWN-2020BR/DPC | G41: 115G | H41: 295T | U41: 250G
C42: BOM-SB1368CA (JS1001 PU 뺀 VER.) | G42: 122G | H42: 470T | U42: 390G
... C52: CVST19BM0027 | G52: 65G | H52: 420T | U52: 100G
C53: NEO-22F231 (10mic) | U53: 184G
C54: SK-20-0621-3F(고투습) | U54: 120G
...

Sheet RAW_DX(DJ)
B1: 2026FW 다운 | AK1: =AK3/'DJ 2025 FW'!AK3-1 -> 2.0285644 | AL1: =AL3/'DJ 2025 FW'!AL3-1 -> 1.991261 | AM1: =AM3/'DJ 2025 FW'!AQ3-1 -> 0.31515383 | AN1: =AN3/'DJ 2025 FW'!AR3-1 -> 0.32923885 | AO1: =AO3-'DJ 2025 FW'!AS3 -> -0.31933701
B2: ▶제품 기준 정보 | M2: ▶소재 스팩 정보 | X2: ▶소재 외관 정보 | AB2: ▶다운백 정보 | AE2: ▶충전재 정보 | AI2: ▶디자인 정보 | AK2: ▶발주, 판매 정보
I3: =SUBTOTAL(9,$I$5:$I$936) -> 43 | J3: =SUBTOTAL(9,$J$5:$J$936) -> 240 | K3: =SUBTOTAL(9,$K$5:$K$936) -> 750 | Z3: Ra값 (Roughness Average) | AA3: GU값 (Gloss Units) | AK3: =SUBTOTAL(9,AK5:AK936) -> 1927018 | AL3: =SUBTOTAL(9,AL5:AL936) -> 626501355000 | AM3: =SUBTOTAL(9,AM5:AM936) -> 472335 | AN3: =SUBTOTAL(9,AN5:AN936) -> 141758104080 | AO3: =AM3/AK3 -> 0.24511188
B4: 품번 (9자리) | C4: 품번 (5자리) | D4: 발주 구분 | E4: 성별 코드 | F4: 아이템코드 | G4: 시즌 | H4: 제품명 | I4: 디자인수 | J4: 스타일수 | K4: 컬러수 | L4: 예상TAG가 | M4: 소재처 | N4: 소재명 | O4: 소재 혼용율 | P4: 소재 혼용율% | Q4: 원사 데니아(D) | R4: 소재 중량(G) | S4: 소재 밀도(T) | T4: 레이어(필름) | U4: 레이어(필름) 두께 | V4: 소재 후가공 | W4: 소재 TAG | X4: 소재 구분 | Y4: 소재 조직 | Z4: 소재 텍스쳐(Ra) LEVEL | AA4: 소재 광택(GU) LEVEL | AB4: 다운백 구조 | AC4: 다운백 데니아(D) | AD4: 다운백 밀도(T) | AE4: 충전재 사종 | AF4: 충전재양(G) | AG4: 중량 구분 | AH4: 필파워 | AI4: 디자인 형태 | AJ4: 기장 | AK4: 발주 수량 | AL4: 발주 금액 | AM4: 목표 판매 수량 | AN4: 목표 판매 금액 | AO4: 목표 판매율 | AQ4: 디자이너
A5: =B5&I5 -> DWDJ9F0661 | B5: DWDJ9F066 | C5: =MID(B5,3,5) -> DJ9F0 | D5: MAIN | E5: =MID($B5,2,1) -> W | F5: =MID($B5,3,2) -> DJ | G5: WINTER | H5: 여성 올핀 다운 경량패딩 | I5: 1 | J5: 1 | K5: 3 | L5: 249000 | M5: C&A | N5: CAC-CN6811 2T | O5: NYLON | P5: 100 | Q5: 20D | R5: 40G | S5: 400T | T5: Single L | V5: CIRE | X5: 우븐 | Y5: PLAIN | Z5: Ra_LV1 | AA5: GU_LV5 | AB5: 4L 구조 | AC5: 20D | AD5: 400T | AE5: EU DUCK 8020 | AF5: 110G | AG5: 중량 | AH5: 650 | AI5: 중량패딩 | AJ5: 크롭 | AK5: 4000 | AL5: =AK5*L5 -> 996000000 | AM5: =AK5*AO5 -> 2600 | AN5: =(AM5*L5)*92% -> 595608000 | AO5: 0.65 | AQ5: 엄윤재
A6: =B6&I6 -> DWDJ9Q0661 | B6: DWDJ9Q066 | C6: =MID(B6,3,5) -> DJ9Q0 | D6: MAIN | E6: =MID($B6,2,1) -> W | F6: =MID($B6,3,2) -> DJ | G6: WINTER | H6: 여성 하이브리드 튜브 구스다운 경량패딩 | I6: 1 | J6: =IF(B6=B5,"",1) -> 1 | K6: 3 | L6: 269000 | M6: 영보 | N6: PN-3972S-5 | O6: POLYESTER/POLYURETHANE | P6: 90/10 | Q6: 30D | R6: 165G | S6: 443T | T6: Single L | V6: WR | X6: 우븐 | Y6: TUBE | Z6: Ra_LV2 | AA6: GU_LV2 | AB6: 2L 구조(튜브) | AC6: (다운백 없음) | AD6: (다운백 없음) | AE6: EU GOOSE 8020 | AF6: 60G | AG6: 경량 | AH6: 650 | AI6: 경량패딩 | AJ6: 스탠다드 | AK6: 3300 | AL6: =AK6*L6 -> 887700000 | AM6: =AK6*AO6 -> 2145 | AN6: =(AM6*L6)*92% -> 530844600 | AO6: =$AO$5 -> 0.65 | AQ6: 엄윤재
A7: =B7&I7 -> DWDJ920661 | B7: DWDJ92066 | C7: =MID(B7,3,5) -> DJ920 | D7: MAIN | E7: =MID($B7,2,1) -> W | F7: =MID($B7,3,2) -> DJ | G7: WINTER | H7: 여성 멜로즈 튜브 다운 경량패딩 | I7: 1 | J7: =IF(B7=B6,"",1) -> 1 | K7: 4 | L7: 299000 | M7: 영보 | N7: PF-23032-12 (P30D 사각 튜브) 12CM | O7: POLYESTER | P7: 100 | Q7: 30D | R7: 135G | S7: 442T | T7: Single L | V7: WR | X7: 우븐 | Y7: TUBE | Z7: Ra_LV2 | AA7: GU_LV2 | AB7: 2L 구조(튜브) | AC7: (다운백 없음) | AD7: (다운백 없음) | AE7: EU DUCK 8020 | AF7: 165G | AG7: 중량 | AH7: 650 | AI7: 중량패딩 | AJ7: 세미크롭 | AK7: 6000 | AL7: =AK7*L7 -> 1794000000 | AM7: =AK7*AO7 -> 3900 | AN7: =(AM7*L7)*92% -> 1072812000 | AO7: =$AO$5 -> 0.65 | AQ7: 엄윤재
A8: =B8&I8 -> DWDJ9H066 | B8: DWDJ9H066 | C8: =MID(B8,3,5) -> DJ9H0 | D8: MAIN | E8: =MID($B8,2,1) -> W | F8: =MID($B8,3,2) -> DJ | G8: WINTER | H8: 여성 멜로즈 튜브 다운 미드패딩 | J8: =IF(B8=B7,"",1) -> 1 | K8: 3 | L8: 319000 | M8: 영보 | N8: PF-23032-12C (12CM사각_cire) | O8: POLYESTER | P8: 100 | Q8: 30D | R8: 135G | S8: 442T | T8: Single L | V8: WR, CIRE | X8: 우븐 | Y8: TUBE | Z8: Ra_LV2 | AA8: GU_LV2 | AB8: 2L 구조(튜브) | AC8: (다운백 없음) | AD8: (다운백 없음) | AE8: EU DUCK 8020 | AF8: 140G | AG8: 중량 | AH8: 650 | AI8: 중량패딩 | AJ8: 미드 | AK8: 3500 | AL8: =AK8*L8 -> 1116500000 | AM8: =AK8*AO8 -> 2275 | AN8: =(AM8*L8)*92% -> 667667000 | AO8: =$AO$5 -> 0.65 | AQ8: 엄윤재
A9: =B9&I9 -> DWDJ930661 | B9: DWDJ93066 | C9: =MID(B9,3,5) -> DJ930 | D9: MAIN | E9: =MID($B9,2,1) -> W | F9: =MID($B9,3,2) -> DJ | G9: WINTER | H9: 여성 올리브 글로우 다운 숏패딩(기본소재) | I9: 1 | J9: =IF(B9=B8,"",1) -> 1 | K9: 4 | L9: 299000 | M9: 원창 | N9: CVST230218C-01 | O9: POLYESTER | P9: 100 | Q9: 50D | R9: 70G | S9: 239T | T9: 2L | U9: 7mic | X9: 우븐 | Y9: PLAIN | Z9: Ra_LV2 | AA9: GU_LV2 | AB9: 4L 구조 | AC9: 20D | AD9: 400T | AE9: EU DUCK 8020 | AF9: 180G | AG9: 헤비 | AH9: 650 | AI9: 크롭패딩 | AJ9: 세미크롭 | AK9: 23000 | AL9: =AK9*L9 -> 6877000000 | AM9: =AK9*AO9 -> 14950 | AN9: =(AM9*L9)*92% -> 4112446000 | AO9: =$AO$5 -> 0.65 | AQ9: 엄윤재
A10: =B10&I10 -> DWDJ93166 | B10: DWDJ93166 | C10: =MID(B10,3,5) -> DJ931 | D10: MAIN | E10: =MID($B10,2,1) -> W | F10: =MID($B10,3,2) -> DJ | G10: WINTER | H10: 여성 올리브 글로우 다운 숏패딩(유광) | J10: =IF(B10=B9,"",1) -> 1 | K10: 3 | L10: 299000 | M10: 플레이트 | N10: PS-1286 | O10: NYLON | P10: 100 | Q10: 20D | R10: 44G | S10: 400T | T10: Single L | V10: WR, CIRE | X10: 우븐 | Y10: PLAIN | Z10: Ra_LV1 | AA10: GU_LV4 | AB10: 4L 구조 | AC10: 20D | AD10: 400T | AE10: EU DUCK 8020 | AF10: 180G | AG10: 헤비 | AH10: 650 | AI10: 크롭패딩 | AJ10: 세미크롭 | AK10: 6500 | AL10: =AK10*L10 -> 1943500000 | AM10: =AK10*AO10 -> 4225 | AN10: =(AM10*L10)*92% -> 1162213000 | AO10: =$AO$5 -> 0.65 | AQ10: 엄윤재
A11: =B11&I11 -> DWDJ940661 | B11: DWDJ94066 | C11: =MID(B11,3,5) -> DJ940 | D11: MAIN | E11: =MID($B11,2,1) -> W | F11: =MID($B11,3,2) -> DJ | G11: WINTER | H11: 여성 올리아 글로우 다운 숏패딩(기본) | I11: 1 | J11: =IF(B11=B10,"",1) -> 1 | K11: 3 | L11: 299000 | M11: 원창 | N11: CVST230218C-01 | O11: POLYESTER | P11: 100 | Q11: 50D | R11: 70G | S11: 239T | T11: 2L | U11: 7mic | X11: 우븐 | Y11: PLAIN | Z11: Ra_LV2 | AA11: GU_LV2 | AB11: 4L 구조 | AC11: 20D | AD11: 400T | AE11: EU DUCK 8020 | AF11: 180G | AG11: 헤비 | AH11: 650 | AI11: 크롭패딩 | AJ11: 크롭 | AK11: 17000 | AL11: =AK11*L11 -> 5083000000 | AM11: =AK11*AO11 -> 11050 | AN11: =(AM11*L11)*92% -> 3039634000 | AO11: =$AO$5 -> 0.65 | AQ11: 엄윤재
A12: =B12&I12 -> DWDJ94166 | B12: DWDJ94166 | C12: =MID(B12,3,5) -> DJ941 | D12: MAIN | E12: =MID($B12,2,1) -> W | F12: =MID($B12,3,2) -> DJ | G12: WINTER | H12: 여성 올리아 글로우 다운 숏패딩(유광) | J12: =IF(B12=B11,"",1) -> 1 | K12: 3 | L12: 299000 | M12: C&A | N12: CAC-CN6811 2T | O12: NYLON | P12: 100 | Q12: 20D | R12: 40G | S12: 400T | T12: Single L | V12: CIRE | X12: 우븐 | Y12: PLAIN | Z12: Ra_LV2 | AA12: GU_LV4 | AB12: 4L 구조 | AC12: 20D | AD12: 400T | AE12: EU DUCK 8020 | AF12: 180G | AG12: 헤비 | AH12: 650 | AI12: 크롭패딩 | AJ12: 크롭 | AK12: =3000+4000+1000 -> 8000 | AL12: =AK12*L12 -> 2392000000 | AM12: =AK12*AO12 -> 5200 | AN12: =(AM12*L12)*92% -> 1430416000 | AO12: =$AO$5 -> 0.65 | AQ12: 엄윤재
A13: =B13&I13 -> DWDJ9R0661 | B13: DWDJ9R066 | C13: =MID(B13,3,5) -> DJ9R0 | D13: MAIN | E13: =MID($B13,2,1) -> W | F13: =MID($B13,3,2) -> DJ | G13: WINTER | H13: 여성 뉴올리아 글로우 다운 숏패딩(벨벳) | I13: 1 | J13: =IF(B13=B12,"",1) -> 1 | K13: 2 | L13: 309000 | M13: 26STORY | N13: 26-BELLINA-1003 | O13: POLYURETHANE | P13: 100 | Q13: 50D | R13: 160G | S13: 290T | T13: Single L | X13: 우븐 | Y13: PLAIN | Z13: Ra_LV1 | AA13: GU_LV4 | AB13: 4L 구조 | AC13: 20D | AD13: 400T | AE13: EU DUCK 8020 | AF13: 170G | AG13: 헤비 | AH13: 650 | AI13: 크롭패딩 | AJ13: 크롭 | AK13: 18000 | AL13: =AK13*L13 -> 5562000000 | AM13: =AK13*AO13 -> 11700 | AN13: =(AM13*L13)*92% -> 3326076000 | AO13: =$AO$5 -> 0.65 | AQ13: 엄윤재
A14: =B14&I14 -> DWDJ9R166 | B14: DWDJ9R166 | C14: =MID(B14,3,5) -> DJ9R1 | D14: MAIN | E14: =MID($B14,2,1) -> W | F14: =MID($B14,3,2) -> DJ | G14: WINTER | H14: 여성 뉴올리아 글로우 다운 숏패딩(NEW소재) | J14: =IF(B14=B13,"",1) -> 1 | K14: 2 | L14: 309000 | M14: BKT | N14: BKW-WMS-028 | O14: POLYURETHANE | P14: 100 | Q14: 20D | R14: 77G | S14: 400T | T14: Single L | X14: 우븐 | Y14: PLAIN | Z14: Ra_LV4 | AA14: GU_LV5 | AB14: 4L 구조 | AC14: 20D | AD14: 400T | AE14: EU DUCK 8020 | AF14: 170G | AG14: 헤비 | AH14: 650 | AI14: 크롭패딩 | AJ14: 크롭 | AK14: 6000 | AL14: =AK14*L14 -> 1854000000 | AM14: =AK14*AO14 -> 3900 | AN14: =(AM14*L14)*92% -> 1108692000 | AO14: =$AO$5 -> 0.65 | AQ14: 엄윤재
A15: =B15&I15 -> DWDJ9G0661 | B15: DWDJ9G066 | C15: =MID(B15,3,5) -> DJ9G0 | D15: MAIN | E15: =MID($B15,2,1) -> W | F15: =MID($B15,3,2) -> DJ | G15: WINTER | H15: 여성 헤이니 글로우 다운 숏패딩(기본소재) | I15: 1 | J15: =IF(B15=B14,"",1) -> 1 | K15: 3 | L15: 299000 | M15: TOPTEX | N15: N2040CT | O15: NYLON | P15: 100 | Q15: 20D | R15: 39G | S15: 400T | T15: Single L | V15: WR | X15: 우븐 | Y15: PLAIN | Z15: Ra_LV1 | AA15: GU_LV3 | AB15: 4L 구조 | AC15: 20D | AD15: 400T | AE15: EU DUCK 8020 | AF15: 140G | AG15: 헤비 | AH15: 650 | AI15: 크롭패딩 | AJ15: 슈퍼크롭 | AK15: =4000+1500+1000 -> 6500 | AL15: =AK15*L15 -> 1943500000 | AM15: =AK15*AO15 -> 4225 | AN15: =(AM15*L15)*92% -> 1162213000 | AO15: =$AO$5 -> 0.65 | AQ15: 엄윤재
A16: =B16&I16 -> DWDJ9G166 | B16: DWDJ9G166 | C16: =MID(B16,3,5) -> DJ9G1 | D16: MAIN | E16: =MID($B16,2,1) -> W | F16: =MID($B16,3,2) -> DJ | G16: WINTER | H16: 여성 헤이니 글로우 다운 숏패딩(벨벳) | J16: =IF(B16=B15,"",1) -> 1 | K16: 4 | L16: 299000 | M16: 26STORY | N16: 26-BELLINA-1003 | O16: POLYURETHANE | P16: 100 | Q16: 50D | R16: 160G | S16: 290T | T16: Single L | X16: 우븐 | Y16: PLAIN | Z16: Ra_LV1 | AA16: GU_LV4 | AB16: 4L 구조 | AC16: 20D | AD16: 400T | AE16: EU DUCK 8020 | AF16: 140G | AG16: 헤비 | AH16: 650 | AI16: 크롭패딩 | AJ16: 슈퍼크롭 | AK16: 10500 | AL16: =AK16*L16 -> 3139500000 | AM16: =AK16*AO16 -> 6825 | AN16: =(AM16*L16)*92% -> 1877421000 | AO16: =$AO$5 -> 0.65 | AQ16: 엄윤재
A17: =B17&I17 -> DWDJ9G266 | B17: DWDJ9G266 | C17: =MID(B17,3,5) -> DJ9G2 | D17: MAIN | E17: =MID($B17,2,1) -> W | F17: =MID($B17,3,2) -> DJ | G17: WINTER | H17: 여성 헤이니 글로우 다운 숏패딩(애슬레져) | J17: 1 | K17: 2 | L17: 299000 | O17: NYLON | P17: 100 | Q17: 10D | R17: 29G | S17: 505T | T17: Single L | V17: WR | X17: 우븐 | Y17: RIPSTOP | Z17: Ra_LV2 | AA17: GU_LV2 | AB17: 2L 구조 | AC17: (다운백 없음) | AD17: (다운백 없음) | AE17: EU DUCK 8020 | AF17: 130G | AG17: 헤비 | AH17: 650 | AI17: 크롭패딩 | AJ17: 슈퍼크롭 | AK17: 5000 | AL17: =AK17*L17 -> 1495000000 | AM17: =AK17*AO17 -> 3250 | AN17: =(AM17*L17)*92% -> 894010000 | AO17: =$AO$5 -> 0.65 | AQ17: 엄윤재
A18: =B18&I18 -> DWDJ910661 | B18: DWDJ91066 | C18: =MID(B18,3,5) -> DJ910 | D18: MAIN | E18: =MID($B18,2,1) -> W | F18: =MID($B18,3,2) -> DJ | G18: WINTER | H18: 여성 카라형 다운 숏패딩 | I18: 1 | J18: =IF(B18=B16,"",1) -> 1 | K18: 4 | L18: 319000 | M18: C&A | N18: CAC-KM0023 | O18: POLYURETHANE | P18: 100 | Q18: 50D | R18: 97G | S18: 300T | T18: 2L | X18: 우븐 | Y18: PLAIN | Z18: Ra_LV1 | AA18: GU_LV4 | AB18: 4L 구조 | AC18: 20D | AD18: 400T | AE18: EU DUCK 8020 | AF18: 150G | AG18: 헤비 | AH18: 650 | AI18: 크롭패딩 | AJ18: 크롭 | AK18: 8300 | AL18: =AK18*L18 -> 2647700000 | AM18: =AK18*AO18 -> 5395 | AN18: =(AM18*L18)*92% -> 1583324600 | AO18: =$AO$5 -> 0.65 | AQ18: 엄윤재
A19: =B19&I19 -> DWDJ9S0661 | B19: DWDJ9S066 | C19: =MID(B19,3,5) -> DJ9S0 | D19: MAIN | E19: =MID($B19,2,1) -> W | F19: =MID($B19,3,2) -> DJ | G19: WINTER | H19: 여성 애슬레져 다운 숏패딩 (코듀로이) | I19: 1 | J19: =IF(B19=B18,"",1) -> 1 | K19: 2 | L19: 319000 | M19: BKT | N19: BKW-WMS-603 | O19: POLYESTER/POLYURETHANE | P19: 95/5 | Q19: 50D | R19: 225G | S19: (니트소재 밀도 없음) | T19: Single L | X19: 니트 | Y19: CODUROY | Z19: Ra_LV5 | AA19: GU_LV2 | AB19: 4L 구조 | AC19: 20D | AD19: 400T | AE19: EU DUCK 8020 | AF19: 140G | AG19: 중량 | AH19: 650 | AI19: 크롭패딩 | AJ19: 슈퍼크롭 | AK19: 4000 | AL19: =AK19*L19 -> 1276000000 | AM19: =AK19*AO19 -> 2600 | AN19: =(AM19*L19)*92% -> 763048000 | AO19: =$AO$5 -> 0.65 | AQ19: 엄윤재
A20: =B20&I20 -> DWDJ9S166 | B20: DWDJ9S166 | C20: =MID(B20,3,5) -> DJ9S1 | D20: MAIN | E20: =MID($B20,2,1) -> W | F20: =MID($B20,3,2) -> DJ | G20: WINTER | H20: 여성 애슬레져 다운 숏패딩 (플리스) | J20: =IF(B20=B19,"",1) -> 1 | K20: 2 | L20: 319000 | M20: KOA | N20: KA2508-01C | O20: POLYESTER | P20: 100 | Q20: 75D | R20: 370G | S20: (니트소재 밀도 없음) | T20: Single L | X20: 니트 | Y20: BOA | Z20: Ra_LV5 | AA20: GU_LV2 | AB20: 4L 구조 | AC20: 20D | AD20: 400T | AE20: EU DUCK 8020 | AF20: 130G | AG20: 중량 | AH20: 650 | AI20: 크롭패딩 | AJ20: 슈퍼크롭 | AK20: 4500 | AL20: =AK20*L20 -> 1435500000 | AM20: =AK20*AO20 -> 2925 | AN20: =(AM20*L20)*92% -> 858429000 | AO20: =$AO$5 -> 0.65 | AQ20: 엄윤재
A21: =B21&I21 -> DWDJ960661 | B21: DWDJ96066 | C21: =MID(B21,3,5) -> DJ960 | D21: MAIN | E21: =MID($B21,2,1) -> W | F21: =MID($B21,3,2) -> DJ | G21: WINTER | H21: 여성 베니아 구스다운 미드패딩(기본소재) | I21: 1 | J21: =IF(B21=B20,"",1) -> 1 | K21: 2 | L21: 379000 | M21: TOPTEX | N21: N2040CT | O21: NYLON | P21: 100 | Q21: 20D | R21: 39G | S21: 400T | T21: Single L | V21: WR | X21: 우븐 | Y21: PLAIN | Z21: Ra_LV1 | AA21: GU_LV3 | AB21: 4L 구조 | AC21: 20D | AD21: 400T | AE21: EU GOOSE 8020 | AF21: 160G | AG21: 헤비 | AH21: 650 | AI21: 미드패딩 | AJ21: 미드 | AK21: 4000 | AL21: =AK21*L21 -> 1516000000 | AM21: =AK21*AO21 -> 2600 | AN21: =(AM21*L21)*92% -> 906568000 | AO21: =$AO$5 -> 0.65 | AQ21: 엄윤재
A22: =B22&I22 -> DWDJ96166 | B22: DWDJ96166 | C22: =MID(B22,3,5) -> DJ961 | D22: MAIN | E22: =MID($B22,2,1) -> W | F22: =MID($B22,3,2) -> DJ | G22: WINTER | H22: 여성 베니아 구스다운 미드패딩(더블립스탑) | J22: =IF(B22=B21,"",1) -> 1 | K22: 2 | L22: 379000 | M22: SPM | N22: ACNE_DT 15 | O22: NYLON | P22: 100 | Q22: 15D | R22: 40G | S22: 441T | T22: Single L | V22: WR | X22: 우븐 | Y22: RIPSTOP | Z22: Ra_LV3 | AA22: GU_LV3 | AB22: 4L 구조 | AC22: 20D | AD22: 400T | AE22: EU GOOSE 8020 | AF22: 160G | AG22: 헤비 | AH22: 650 | AI22: 미드패딩 | AJ22: 미드 | AK22: 3000 | AL22: =AK22*L22 -> 1137000000 | AM22: =AK22*AO22 -> 1950 | AN22: =(AM22*L22)*92% -> 679926000 | AO22: =$AO$5 -> 0.65 | AQ22: 엄윤재
A23: =B23&I23 -> DWDJ990661 | B23: DWDJ99066 | C23: =MID(B23,3,5) -> DJ990 | D23: MAIN | E23: =MID($B23,2,1) -> W | F23: =MID($B23,3,2) -> DJ | G23: WINTER | H23: 여성 켈리 구스다운 숏패딩 | I23: 1 | J23: =IF(B23=B22,"",1) -> 1 | K23: 4 | L23: 399000 | M23: 네오드림 | N23: NEO-226F128 | O23: POLYESTER | P23: 100 | Q23: 75D | R23: 90G | S23: 203T | T23: 2L | U23: 8mic | V23: WR | X23: 우븐 | Y23: PLAIN | Z23: Ra_LV2 | AA23: GU_LV2 | AB23: 4L 구조 | AC23: 30D | AD23: 360T | AE23: EU GOOSE 8020 | AF23: 180G | AG23: 헤비 | AH23: 650 | AI23: 크롭패딩 | AJ23: 세미크롭 | AK23: 11000 | AL23: =AK23*L23 -> 4389000000 | AM23: =AK23*AO23 -> 7150 | AN23: =(AM23*L23)*92% -> 2624622000 | AO23: =$AO$5 -> 0.65 | AQ23: 엄윤재
A24: =B24&I24 -> DWDJ98066 | B24: DWDJ98066 | C24: =MID(B24,3,5) -> DJ980 | D24: MAIN | E24: =MID($B24,2,1) -> W | F24: =MID($B24,3,2) -> DJ | G24: WINTER | H24: 여성 켈리 구스다운 미드패딩 | J24: =IF(B24=B23,"",1) -> 1 | K24: 4 | L24: 499000 | M24: 네오드림 | N24: NEO-226F128 | O24: POLYESTER | P24: 100 | Q24: 75D | R24: 90G | S24: 203T | T24: 2L | U24: 8mic | V24: WR | X24: 우븐 | Y24: PLAIN | Z24: Ra_LV2 | AA24: GU_LV2 | AB24: 4L 구조 | AC24: 30D | AD24: 360T | AE24: EU GOOSE 8020 | AF24: 210G | AG24: 헤비 | AH24: 650 | AI24: 미드패딩 | AJ24: 미드 | AK24: 9500 | AL24: =AK24*L24 -> 4740500000 | AM24: =AK24*AO24 -> 6175 | AN24: =(AM24*L24)*92% -> 2834819000 | AO24: =$AO$5 -> 0.65 | AQ24: 엄윤재
A25: =B25&I25 -> DWDJ9A066 | B25: DWDJ9A066 | C25: =MID(B25,3,5) -> DJ9A0 | D25: MAIN | E25: =MID($B25,2,1) -> W | F25: =MID($B25,3,2) -> DJ | G25: WINTER | H25: 여성 켈리 구스다운 롱패딩 (기본) | J25: =IF(B25=B24,"",1) -> 1 | K25: 3 | L25: 590000 | M25: 네오드림 | N25: NEO-226F128 | O25: POLYESTER | P25: 100 | Q25: 75D | R25: 90G | S25: 203T | T25: 2L | U25: 8mic | V25: WR | X25: 우븐 | Y25: PLAIN | Z25: Ra_LV2 | AA25: GU_LV2 | AB25: 4L 구조 | AC25: 30D | AD25: 360T | AE25: EU GOOSE 8020 | AF25: 242G | AG25: 헤비 | AH25: 650 | AI25: 롱패딩 | AJ25: 롱 | AK25: 13000 | AL25: =AK25*L25 -> 7670000000 | AM25: =AK25*AO25 -> 8450 | AN25: =(AM25*L25)*92% -> 4586660000 | AO25: =$AO$5 -> 0.65 | AQ25: 엄윤재
A26: =B26&I26 -> DWDJ9A166 | B26: DWDJ9A166 | C26: =MID(B26,3,5) -> DJ9A1 | D26: MAIN | E26: =MID($B26,2,1) -> W | F26: =MID($B26,3,2) -> DJ | G26: WINTER | H26: 여성 켈리 구스다운 롱패딩(유광) | J26: =IF(B26=B25,"",1) -> 1 | K26: 3 | L26: 620000 | M26: 플레이트 | N26: PS-1286 | O26: NYLON | P26: 100 | Q26: 20D | R26: 44G | S26: 400T | T26: Single L | V26: WR, CIRE | X26: 우븐 | Y26: PLAIN | Z26: Ra_LV1 | AA26: GU_LV4 | AB26: 4L 구조 | AC26: 20D | AD26: 400T | AE26: EU GOOSE 8020 | AF26: 242G | AG26: 헤비 | AH26: 650 | AI26: 롱패딩 | AJ26: 롱 | AK26: 3600 | AL26: =AK26*L26 -> 2232000000 | AM26: =AK26*AO26 -> 2340 | AN26: =(AM26*L26)*92% -> 1334736000 | AO26: =$AO$5 -> 0.65 | AQ26: 엄윤재
A27: =B27&I27 -> DMPD750661 | B27: DMPD75066 | C27: =MID(B27,3,5) -> PD750 | D27: MAIN | E27: =MID($B27,2,1) -> M | F27: =MID($B27,3,2) -> PD | G27: WINTER | H27: 남성 올버트 후드 사각퀼팅 경량 볼패딩 | I27: 1 | J27: =IF(B27=B26,"",1) -> 1 | K27: 4 | L27: 209000 | M27: 신한 | N27: SH-FP1440 DC | O27: NYLON | P27: 100 | Q27: 10D | R27: 29G | S27: 477T | T27: Single L | V27: WR | X27: 우븐 | Y27: RIPSTOP | Z27: Ra_LV2 | AA27: GU_LV4 | AB27: 2L 구조 | AC27: (다운백 없음) | AD27: (다운백 없음) | AE27: SynCloud Ball Insulation | AF27: 180G | AG27: 경량 | AI27: 경량패딩 | AJ27: 스탠다드 | AK27: 6500 | AL27: =AK27*L27 -> 1358500000 | AM27: =AK27*AO27 -> 4225 | AN27: =(AM27*L27)*92% -> 812383000 | AO27: =$AO$5 -> 0.65 | AQ27: 허석민
A28: =B28&I28 -> DWPD76066 | B28: DWPD76066 | C28: =MID(B28,3,5) -> PD760 | D28: MAIN | E28: =MID($B28,2,1) -> W | F28: =MID($B28,3,2) -> PD | G28: WINTER | H28: 여성 올버트 후드 사각퀼팅 경량 볼패딩 | J28: =IF(B28=B27,"",1) -> 1 | K28: 3 | L28: 209000 | M28: 신한 | N28: SH-FP1440 DC | O28: NYLON | P28: 100 | Q28: 10D | R28: 29G | S28: 477T | T28: Single L | V28: WR | X28: 우븐 | Y28: RIPSTOP | Z28: Ra_LV2 | AA28: GU_LV4 | AB28: 2L 구조 | AC28: (다운백 없음) | AD28: (다운백 없음) | AE28: SynCloud Ball Insulation | AF28: 133G | AG28: 경량 | AI28: 경량패딩 | AJ28: 스탠다드 | AK28: 3000 | AL28: =AK28*L28 -> 627000000 | AM28: =AK28*AO28 -> 1950 | AN28: =(AM28*L28)*92% -> 374946000 | AO28: =$AO$5 -> 0.65 | AQ28: 허석민
A29: =B29&I29 -> DMDJ7i0661 | B29: DMDJ7i066 | C29: =MID(B29,3,5) -> DJ7i0 | D29: MAIN | E29: =MID($B29,2,1) -> M | F29: =MID($B29,3,2) -> DJ | G29: WINTER | H29: 남성 올버트 후드 다운 경량패딩 | I29: 1 | J29: =IF(B29=B28,"",1) -> 1 | K29: 3 | L29: 259000 | M29: 플레이트 | N29: GD-210C | O29: NYLON | P29: 100 | Q29: 10D | R29: 26G | S29: 505T | T29: Single L | V29: WR | X29: 우븐 | Y29: RIPSTOP | Z29: Ra_LV2 | AA29: GU_LV4 | AB29: 2L 구조 | AC29: (다운백 없음) | AD29: (다운백 없음) | AE29: EU DUCK 9010 | AF29: 110G | AG29: 경량 | AH29: 700 | AI29: 경량패딩 | AJ29: 스탠다드 | AK29: 5000 | AL29: =AK29*L29 -> 1295000000 | AM29: =AK29*AO29 -> 3250 | AN29: =(AM29*L29)*92% -> 774410000 | AO29: =$AO$5 -> 0.65 | AQ29: 허석민
A30: =B30&I30 -> DWDJ7J066 | B30: DWDJ7J066 | C30: =MID(B30,3,5) -> DJ7J0 | D30: MAIN | E30: =MID($B30,2,1) -> W | F30: =MID($B30,3,2) -> DJ | G30: WINTER | H30: 여성 올버트 후드 다운 경량패딩 | J30: =IF(B30=B29,"",1) -> 1 | K30: 3 | L30: 259000 | M30: 플레이트 | N30: GD-210C | O30: NYLON | P30: 100 | Q30: 10D | R30: 26G | S30: 505T | T30: Single L | V30: WR | X30: 우븐 | Y30: RIPSTOP | Z30: Ra_LV2 | AA30: GU_LV4 | AB30: 2L 구조 | AC30: (다운백 없음) | AD30: (다운백 없음) | AE30: EU DUCK 9010 | AF30: 85G | AG30: 경량 | AH30: 700 | AI30: 경량패딩 | AJ30: 스탠다드 | AK30: 2600 | AL30: =AK30*L30 -> 673400000 | AM30: =AK30*AO30 -> 1690 | AN30: =(AM30*L30)*92% -> 402693200 | AO30: =$AO$5 -> 0.65 | AQ30: 허석민
A31: =B31&I31 -> DMDJ7M0661 | B31: DMDJ7M066 | C31: =MID(B31,3,5) -> DJ7M0 | D31: MAIN | E31: =MID($B31,2,1) -> M | F31: =MID($B31,3,2) -> DJ | G31: WINTER | H31: 남성 올버트 뉴퀼팅 구스다운 경량패딩 | I31: 1 | J31: =IF(B31=B30,"",1) -> 1 | K31: 4 | L31: 279000 | M31: 신한 | N31: SL-1417CT | O31: NYLON | P31: 100 | Q31: 15D | R31: 38G | S31: 491T | T31: Single L | V31: WR, CIRE | X31: 우븐 | Y31: RIPSTOP | Z31: Ra_LV3 | AA31: GU_LV3 | AB31: 4L 구조 | AC31: 20D | AD31: 400T | AE31: EU GOOSE 8020 | AF31: 115G | AG31: 경량 | AH31: 650 | AI31: 경량패딩 | AJ31: 스탠다드 | AK31: 4600 | AL31: =AK31*L31 -> 1283400000 | AM31: =AK31*AO31 -> 2990 | AN31: =(AM31*L31)*92% -> 767473200 | AO31: =$AO$5 -> 0.65 | AQ31: 허석민
A32: =B32&I32 -> DWDJ9M066 | B32: DWDJ9M066 | C32: =MID(B32,3,5) -> DJ9M0 | D32: MAIN | E32: =MID($B32,2,1) -> W | F32: =MID($B32,3,2) -> DJ | G32: WINTER | H32: 여성 올버트 뉴퀼팅 구스다운 경량패딩 | J32: =IF(B32=B31,"",1) -> 1 | K32: 4 | L32: 279000 | M32: 신한 | N32: SL-1417CT | O32: NYLON | P32: 100 | Q32: 15D | R32: 38G | S32: 491T | T32: Single L | V32: WR, CIRE | X32: 우븐 | Y32: RIPSTOP | Z32: Ra_LV3 | AA32: GU_LV3 | AB32: 4L 구조 | AC32: 20D | AD32: 400T | AE32: EU GOOSE 8020 | AF32: 90G | AG32: 경량 | AH32: 650 | AI32: 경량패딩 | AJ32: 크롭 | AK32: 7800 | AL32: =AK32*L32 -> 2176200000 | AM32: =AK32*AO32 -> 5070 | AN32: =(AM32*L32)*92% -> 1301367600 | AO32: =$AO$5 -> 0.65 | AQ32: 엄윤재
A33: =B33&I33 -> DMDJ7G0661 | B33: DMDJ7G066 | C33: =MID(B33,3,5) -> DJ7G0 | D33: MAIN | E33: =MID($B33,2,1) -> M | F33: =MID($B33,3,2) -> DJ | G33: WINTER | H33: 남성 올버트 구스다운 숏패딩 (퍼텍스) | I33: 1 | J33: =IF(B33=B32,"",1) -> 1 | K33: 3 | L33: 499000 | M33: PERTEX | N33: PRD812-NFC | O33: NYLON | P33: 100 | Q33: 20D | R33: 38G | S33: 400T | T33: Single L | V33: WR | W33: PERTEX | X33: 우븐 | Y33: PLAIN | Z33: Ra_LV1 | AA33: GU_LV5 | AB33: 2L 구조 | AC33: (다운백 없음) | AD33: (다운백 없음) | AE33: EU GOOSE 9010 | AF33: 240G | AG33: 헤비 | AH33: 700 | AI33: 숏패딩 | AJ33: 스탠다드 | AK33: 6000 | AL33: =AK33*L33 -> 2994000000 | AM33: =AK33*AO33 -> 3900 | AN33: =(AM33*L33)*92% -> 1790412000 | AO33: =$AO$5 -> 0.65 | AQ33: 허석민
A34: =B34&I34 -> DWDJ7H066 | B34: DWDJ7H066 | C34: =MID(B34,3,5) -> DJ7H0 | D34: MAIN | E34: =MID($B34,2,1) -> W | F34: =MID($B34,3,2) -> DJ | G34: WINTER | H34: 여성 올버트 구스다운 숏패딩 (퍼텍스) | J34: =IF(B34=B33,"",1) -> 1 | K34: 2 | L34: 499000 | M34: PERTEX | N34: PRD812-NFC | O34: NYLON | P34: 100 | Q34: 20D | R34: 38G | S34: 400T | T34: Single L | V34: WR | W34: PERTEX | X34: 우븐 | Y34: PLAIN | Z34: Ra_LV1 | AA34: GU_LV5 | AB34: 2L 구조 | AC34: (다운백 없음) | AD34: (다운백 없음) | AE34: EU GOOSE 9010 | AF34: 195G | AG34: 헤비 | AH34: 700 | AI34: 숏패딩 | AJ34: 스탠다드 | AK34: 3000 | AL34: =AK34*L34 -> 1497000000 | AM34: =AK34*AO34 -> 1950 | AN34: =(AM34*L34)*92% -> 895206000 | AO34: =$AO$5 -> 0.65 | AQ34: 허석민
A35: =B35&I35 -> DWDJ9J0661 | B35: DWDJ9J066 | C35: =MID(B35,3,5) -> DJ9J0 | D35: MAIN | E35: =MID($B35,2,1) -> W | F35: =MID($B35,3,2) -> DJ | G35: WINTER | H35: 여성 올버트 다운 크롭 숏패딩 | I35: 1 | J35: =IF(B35=B34,"",1) -> 1 | K35: 4 | L35: 329000 | M35: 플레이트 | N35: GD-210C | O35: NYLON | P35: 100 | Q35: 10D | R35: 26G | S35: 505T | T35: Single L | V35: WR | X35: 우븐 | Y35: RIPSTOP | Z35: Ra_LV2 | AA35: GU_LV2 | AB35: 2L 구조 | AC35: (다운백 없음) | AD35: (다운백 없음) | AE35: EU DUCK 9010 | AF35: 130G | AG35: 중량 | AH35: 650 | AI35: 크롭패딩 | AJ35: 슈퍼크롭 | AK35: 8000 | AL35: =AK35*L35 -> 2632000000 | AM35: =AK35*AO35 -> 5200 | AN35: =(AM35*L35)*92% -> 1573936000 | AO35: =$AO$5 -> 0.65 | AQ35: 엄윤재
A36: =B36&I36 -> DMDJ7U0661 | B36: DMDJ7U066 | C36: =MID(B36,3,5) -> DJ7U0 | D36: MAIN | E36: =MID($B36,2,1) -> M | F36: =MID($B36,3,2) -> DJ | G36: WINTER | H36: 남성 NEW 리조트 사파리 구스다운 미드패딩 | I36: 1 | J36: =IF(B36=B35,"",1) -> 1 | K36: 3 | L36: 690000 | M36: 플레이트 | N36: GL-151C | O36: NYLON/POLYURETHANE | P36: 88/12 | Q36: 70D | R36: 172G | S36: 305T | T36: 2L | U36: 20mic | X36: 우븐 | Y36: TWILL | Z36: Ra_LV2 | AA36: GU_LV2 | AB36: 4L 구조 | AC36: 20D | AD36: 400T | AE36: EU GOOSE 8020 | AF36: 290G | AG36: 헤비 | AH36: 650 | AI36: 미드패딩 | AJ36: 미드 | AK36: 4300 | AL36: =AK36*L36 -> 2967000000 | AM36: =AK36*AO36 -> 2795 | AN36: =(AM36*L36)*92% -> 1774266000 | AO36: =$AO$5 -> 0.65 | AQ36: 허석민
A37: =B37&I37 -> DMDJ7K0661 | B37: DMDJ7K066 | C37: =MID(B37,3,5) -> DJ7K0 | D37: MAIN | E37: =MID($B37,2,1) -> M | F37: =MID($B37,3,2) -> DJ | G37: WINTER | H37: 남성 베르겐 고어 윈드스토퍼 구스다운 숏패딩 | I37: 1 | J37: =IF(B37=B36,"",1) -> 1 | K37: 2 | L37: 520000 | M37: GORE | N37: BNRSPL75ES-PX 2L | O37: POLYESTER | P37: 100 | Q37: 75D | R37: 100G | S37: 300T | T37: 2L | U37: 30mic | V37: DWR | W37: GORE-TEX | X37: 우븐 | Y37: PLAIN | Z37: Ra_LV2 | AA37: GU_LV2 | AB37: 4L 구조 | AC37: 20D | AD37: 400T | AE37: EU GOOSE 8020 | AF37: 220G | AG37: 헤비 | AH37: 650 | AI37: 숏패딩 | AJ37: 스탠다드 | AK37: 6300 | AL37: =AK37*L37 -> 3276000000 | AM37: =AK37*AO37 -> 4095 | AN37: =(AM37*L37)*92% -> 1959048000 | AO37: =$AO$5 -> 0.65 | AQ37: 허석민
A38: =B38&I38 -> DMDJ7O0661 | B38: DMDJ7O066 | C38: =MID(B38,3,5) -> DJ7O0 | D38: MAIN | E38: =MID($B38,2,1) -> M | F38: =MID($B38,3,2) -> DJ | G38: WINTER | H38: 남성 밀포드 베르텍스 구스다운 롱패딩 | I38: 1 | J38: =IF(B38=B37,"",1) -> 1 | K38: 2 | L38: 750000 | M38: TOPTEX | N38: TFCT-9039 (3K/3K 2L) | O38: NYLON/POLYURETHANE | P38: 95/5 | Q38: 70D | R38: 135G | S38: 210T | T38: 2L | U38: 20mic | V38: WR | W38: BERTEX | X38: 우븐 | Y38: PLAIN | Z38: Ra_LV3 | AA38: GU_LV2 | AB38: 4L 구조 | AC38: 20D | AD38: 400T | AE38: EU GOOSE 8020 | AF38: 320G | AG38: 헤비 | AH38: 650 | AI38: 롱패딩 | AJ38: 롱 | AK38: 2300 | AL38: =AK38*L38 -> 1725000000 | AM38: =AK38*AO38 -> 1495 | AN38: =(AM38*L38)*92% -> 1031550000 | AO38: =$AO$5 -> 0.65 | AQ38: 허석민
A39: =B39&I39 -> DWDJ9K0661 | B39: DWDJ9K066 | C39: =MID(B39,3,5) -> DJ9K0 | D39: MAIN | E39: =MID($B39,2,1) -> W | F39: =MID($B39,3,2) -> DJ | G39: WINTER | H39: 여성 밀포드 베르텍스 구스다운 미드패딩 | I39: 1 | J39: =IF(B39=B38,"",1) -> 1 | K39: 2 | L39: 550000 | M39: MOVE | N39: MV-2083 3L | O39: POLYESTER | P39: 100 | Q39: 30D | R39: 120G | S39: 413T | T39: 3L | U39: 20mic | W39: BERTEX | X39: 우븐 | Y39: RIPSTOP | Z39: Ra_LV3 | AA39: GU_LV2 | AB39: 4L 구조 | AC39: 20D | AD39: 400T | AE39: EU GOOSE 8020 | AF39: 175G | AG39: 헤비 | AH39: 650 | AI39: 미드패딩 | AJ39: 미드 | AK39: 2500 | AL39: =AK39*L39 -> 1375000000 | AM39: =AK39*AO39 -> 1625 | AN39: =(AM39*L39)*92% -> 822250000 | AO39: =$AO$5 -> 0.65 | AQ39: 엄윤재
A40: =B40&I40 -> DWDJ9B0661 | B40: DWDJ9B066 | C40: =MID(B40,3,5) -> DJ9B0 | D40: MAIN | E40: =MID($B40,2,1) -> W | F40: =MID($B40,3,2) -> DJ | G40: WINTER | H40: 여성 밀포드 베르텍스 벨티드 구스다운 롱패딩 | I40: 1 | J40: =IF(B40=B39,"",1) -> 1 | K40: 2 | L40: 630000 | M40: MOVE | N40: MV-2083 3L | O40: POLYESTER | P40: 100 | Q40: 30D | R40: 120G | S40: 413T | T40: 3L | U40: 20mic | W40: BERTEX | X40: 우븐 | Y40: RIPSTOP | Z40: Ra_LV3 | AA40: GU_LV2 | AB40: 4L 구조 | AC40: 20D | AD40: 400T | AE40: EU GOOSE 8020 | AF40: 210G | AG40: 헤비 | AH40: 650 | AI40: 롱패딩 | AJ40: 롱 | AK40: 4200 | AL40: =AK40*L40 -> 2646000000 | AM40: =AK40*AO40 -> 2730 | AN40: =(AM40*L40)*92% -> 1582308000 | AO40: =$AO$5 -> 0.65 | AQ40: 엄윤재
...

Sheet DJ 2024 FW
B1: 2024FW 다운
B2: ▶제품 기준 정보 | M2: ▶소재 스팩 정보 | X2: ▶소재 외관 정보 | AB2: ▶다운백 정보 | AE2: ▶충전재 정보 | AI2: ▶디자인 정보 | AK2: ▶발주, 판매 정보 (251207일자)
J3: =SUBTOTAL(9,$J$5:$J$1000) -> 74 | K3: =SUBTOTAL(9,$K$5:$K$1000) -> 254 | Z3: Ra값 (Roughness Average) | AA3: GU값 (Gloss Units) | AK3: =SUBTOTAL(9,AK5:AK1000) -> 663237 | AL3: =SUBTOTAL(9,AL5:AL1000) -> 213075763000 | AM3: =SUBTOTAL(9,AM5:AM1000) -> 34263 | AN3: =SUBTOTAL(9,AN5:AN1000) -> 9895514392 | AO3: =SUBTOTAL(9,AO5:AO1000) -> 206721 | AP3: =SUBTOTAL(9,AP5:AP1000) -> 54082034777 | AQ3: =SUBTOTAL(9,AQ5:AQ1000) -> 393855 | AR3: =SUBTOTAL(9,AR5:AR1000) -> 109427499748 | AS3: =AQ3/AK3 -> 0.5938375
B4: 품번 (9자리) | C4: 품번 (5자리) | D4: 발주 구분 | E4: 성별 코드 | F4: 아이템코드 | G4: 시즌 | H4: 제품명 | I4: 컬러코드 | J4: 스타일수 | K4: 컬러수 | L4: 예상TAG가 | M4: 소재처 | N4: 소재명 | O4: 소재 혼용율 | P4: 소재 혼용율% | Q4: 원사 데니아(D) | R4: 소재 중량(G) | S4: 소재 밀도(T) | T4: 레이어(필름) | U4: 레이어(필름) 두께 | V4: 소재 후가공 | W4: 소재 TAG | X4: 소재 구분 | Y4: 소재 조직 | Z4: 소재 텍스쳐(Ra) LEVEL | AA4: 소재 광택(GU) LEVEL | AB4: 다운백 구조 | AC4: 다운백 데니아(D) | AD4: 다운백 밀도(T) | AE4: 충전재 사종 | AF4: 충전재양(G) | AG4: 중량 구분 | AH4: 필파워 | AI4: 디자인 형태 | AJ4: 기장 | AK4: 발주 수량 | AL4: 발주 금액 | AM4: 주간 판매 수량 | AN4: 주간 판매 금액 | AO4: 누계 판매 수량 | AP4: 누계 판매 금액 | AQ4: 마감 판매 수량 | AR4: 마감 판매 금액 | AS4: 판매율
A5: =B5&I5 -> DWDJ91046VOS | B5: DWDJ91046 | C5: =MID(B5,3,5) -> DJ910 | D5: MAIN | E5: =MID($B5,2,1) -> W | F5: =MID($B5,3,2) -> DJ | G5: WINTER | H5: 여성 벨라 구스다운 경량패딩 | I5: VOS | J5: 1 | K5: 1 | L5: 199000 | M5: 봄텍스 | N5: BOM-SB1368CA (JS1001 PU 뺀 VER.) | O5: POLYESTER | P5: 100 | Q5: 20D | R5: 45G | S5: 435T | T5: Single L | V5: WR | X5: 우븐 | Y5: PLAIN | Z5: Ra_LV1 | AA5: GU_LV4 | AB5: 4L 구조 | AC5: 20D | AD5: 400T | AE5: EU GOOSE 8020 | AF5: 100G | AG5: 중량 | AH5: 650 | AI5: 중량패딩 | AJ5: 크롭 | AK5: 994 | AL5: 197806000 | AM5: 14 | AN5: 1950200 | AO5: 100 | AP5: 15691936 | AQ5: 177 | AR5: 26381316 | AS5: =AQ5/AK5 -> 0.17806841
A6: =B6&I6 -> DWDJ91046BKS | B6: DWDJ91046 | C6: =MID(B6,3,5) -> DJ910 | D6: MAIN | E6: =MID($B6,2,1) -> W | F6: =MID($B6,3,2) -> DJ | G6: WINTER | H6: 여성 벨라 구스다운 경량패딩 | I6: BKS | J6: =IF(B6=B5,"",1) | K6: 1 | L6: 199000 | M6: 봄텍스 | N6: BOM-SB1368CA (JS1001 PU 뺀 VER.) | O6: POLYESTER | P6: 100 | Q6: 20D | R6: 45G | S6: 435T | T6: Single L | V6: WR | X6: 우븐 | Y6: PLAIN | Z6: Ra_LV1 | AA6: GU_LV4 | AB6: 4L 구조 | AC6: 20D | AD6: 400T | AE6: EU GOOSE 8020 | AF6: 100G | AG6: 중량 | AH6: 650 | AI6: 중량패딩 | AJ6: 크롭 | AK6: 1739 | AL6: 346061000 | AM6: 99 | AN6: 13734300 | AO6: 690 | AP6: 103072647 | AQ6: 1177 | AR6: 170517837 | AS6: =AQ6/AK6 -> 0.67682576
A7: =B7&I7 -> DWDJ91046CRS | B7: DWDJ91046 | C7: =MID(B7,3,5) -> DJ910 | D7: MAIN | E7: =MID($B7,2,1) -> W | F7: =MID($B7,3,2) -> DJ | G7: WINTER | H7: 여성 벨라 구스다운 경량패딩 | I7: CRS | J7: =IF(B7=B6,"",1) | K7: 1 | L7: 199000 | M7: 봄텍스 | N7: BOM-SB1368CA (JS1001 PU 뺀 VER.) | O7: POLYESTER | P7: 100 | Q7: 20D | R7: 45G | S7: 435T | T7: Single L | V7: WR | X7: 우븐 | Y7: PLAIN | Z7: Ra_LV1 | AA7: GU_LV4 | AB7: 4L 구조 | AC7: 20D | AD7: 400T | AE7: EU GOOSE 8020 | AF7: 100G | AG7: 중량 | AH7: 650 | AI7: 중량패딩 | AJ7: 크롭 | AK7: 1090 | AL7: 216910000 | AM7: 47 | AN7: 6395540 | AO7: 455 | AP7: 70207429 | AQ7: 726 | AR7: 107673249 | AS7: =AQ7/AK7 -> 0.66605505
A8: =B8&I8 -> DWDJ92046BGS | B8: DWDJ92046 | C8: =MID(B8,3,5) -> DJ920 | D8: MAIN | E8: =MID($B8,2,1) -> W | F8: =MID($B8,3,2) -> DJ | G8: WINTER | H8: 여성 멜로즈 튜브 구스다운 경량패딩 | I8: BGS | J8: =IF(B8=B7,"",1) -> 1 | K8: 1 | L8: 299000 | M8: 영보 | N8: PF-23032 (P30D 사각 튜브) 12CM | O8: POLYESTER | P8: 100 | Q8: 30D | R8: 135G | S8: 442T | T8: Single L | V8: WR | X8: 우븐 | Y8: TUBE | Z8: Ra_LV2 | AA8: GU_LV2 | AB8: 2L 구조(튜브) | AC8: (다운백 없음) | AD8: =AC8 -> (다운백 없음) | AE8: EU GOOSE 8020 | AF8: 150G | AG8: 중량 | AH8: 650 | AI8: 중량패딩 | AJ8: 세미크롭 | AK8: 1808 | AL8: 540592000 | AM8: 172 | AN8: 35747490 | AO8: 1543 | AP8: 349944579 | AQ8: 1771 | AR8: 397526539 | AS8: =AQ8/AK8 -> 0.9795354
A9: =B9&I9 -> DWDJ92046CRS | B9: DWDJ92046 | C9: =MID(B9,3,5) -> DJ920 | D9: MAIN | E9: =MID($B9,2,1) -> W | F9: =MID($B9,3,2) -> DJ | G9: WINTER | H9: 여성 멜로즈 튜브 구스다운 경량패딩 | I9: CRS | J9: =IF(B9=B8,"",1) | K9: 1 | L9: 299000 | M9: 영보 | N9: PF-23032 (P30D 사각 튜브) 12CM | O9: POLYESTER | P9: 100 | Q9: 30D | R9: 135G | S9: 442T | T9: Single L | V9: WR | X9: 우븐 | Y9: TUBE | Z9: Ra_LV2 | AA9: GU_LV2 | AB9: 2L 구조(튜브) | AC9: (다운백 없음) | AD9: =AC9 -> (다운백 없음) | AE9: EU GOOSE 8020 | AF9: 150G | AG9: 중량 | AH9: 650 | AI9: 중량패딩 | AJ9: 세미크롭 | AK9: 1714 | AL9: 512486000 | AM9: 105 | AN9: 21942190 | AO9: 879 | AP9: 198870714 | AQ9: 1334 | AR9: 294079034 | AS9: =AQ9/AK9 -> 0.77829638
A10: =B10&I10 -> DWDJ92046BKS | B10: DWDJ92046 | C10: =MID(B10,3,5) -> DJ920 | D10: MAIN | E10: =MID($B10,2,1) -> W | F10: =MID($B10,3,2) -> DJ | G10: WINTER | H10: 여성 멜로즈 튜브 구스다운 경량패딩 | I10: BKS | J10: =IF(B10=B9,"",1) | K10: 1 | L10: 299000 | M10: 영보 | N10: PF-23032 (P30D 사각 튜브) 12CM | O10: POLYESTER | P10: 100 | Q10: 30D | R10: 135G | S10: 442T | T10: Single L | V10: WR | X10: 우븐 | Y10: TUBE | Z10: Ra_LV2 | AA10: GU_LV2 | AB10: 2L 구조(튜브) | AC10: (다운백 없음) | AD10: =AC10 -> (다운백 없음) | AE10: EU GOOSE 8020 | AF10: 150G | AG10: 중량 | AH10: 650 | AI10: 중량패딩 | AJ10: 세미크롭 | AK10: 3010 | AL10: 899990000 | AM10: 306 | AN10: 63860031 | AO10: 2269 | AP10: 498874200 | AQ10: 2948 | AR10: 640655320 | AS10: =AQ10/AK10 -> 0.97940199
A11: =B11&I11 -> DWDJ9C046BKS | B11: DWDJ9C046 | C11: =MID(B11,3,5) -> DJ9C0 | D11: MAIN | E11: =MID($B11,2,1) -> W | F11: =MID($B11,3,2) -> DJ | G11: WINTER | H11: 여성 멜로즈 튜브 구스다운 경량 미드패딩 | I11: BKS | J11: =IF(B11=B10,"",1) -> 1 | K11: 1 | L11: 319000 | M11: 영보 | N11: PF-23032 (P30D 사각 튜브) 12CM | O11: POLYESTER | P11: 100 | Q11: 30D | R11: 135G | S11: 442T | T11: Single L | V11: WR | X11: 우븐 | Y11: TUBE | Z11: Ra_LV2 | AA11: GU_LV2 | AB11: 2L 구조(튜브) | AC11: (다운백 없음) | AD11: =AC11 -> (다운백 없음) | AE11: EU GOOSE 8020 | AF11: 184G | AG11: 중량 | AH11: 650 | AI11: 미드패딩 | AJ11: 미드 | AK11: 1598 | AL11: 509762000 | AM11: 168 | AN11: 37472290 | AO11: 1302 | AP11: 306833394 | AQ11: 1559 | AR11: 363837824 | AS11: =AQ11/AK11 -> 0.97559449
A12: =B12&I12 -> DWDJ9C046WHS | B12: DWDJ9C046 | C12: =MID(B12,3,5) -> DJ9C0 | D12: MAIN | E12: =MID($B12,2,1) -> W | F12: =MID($B12,3,2) -> DJ | G12: WINTER | H12: 여성 멜로즈 튜브 구스다운 경량 미드패딩 | I12: WHS | J12: =IF(B12=B11,"",1) | K12: 1 | L12: 319000 | M12: 영보 | N12: PF-23032 (P30D 사각 튜브) 12CM | O12: POLYESTER | P12: 100 | Q12: 30D | R12: 135G | S12: 442T | T12: Single L | V12: WR | X12: 우븐 | Y12: TUBE | Z12: Ra_LV2 | AA12: GU_LV2 | AB12: 2L 구조(튜브) | AC12: (다운백 없음) | AD12: =AC12 -> (다운백 없음) | AE12: EU GOOSE 8020 | AF12: 184G | AG12: 중량 | AH12: 650 | AI12: 미드패딩 | AJ12: 미드 | AK12: 1208 | AL12: 385352000 | AM12: 60 | AN12: 13219440 | AO12: 387 | AP12: 90916310 | AQ12: 746 | AR12: 170788380 | AS12: =AQ12/AK12 -> 0.61754967
A13: =B13&I13 -> DWDJ9C046KAS | B13: DWDJ9C046 | C13: =MID(B13,3,5) -> DJ9C0 | D13: MAIN | E13: =MID($B13,2,1) -> W | F13: =MID($B13,3,2) -> DJ | G13: WINTER | H13: 여성 멜로즈 튜브 구스다운 경량 미드패딩 | I13: KAS | J13: =IF(B13=B12,"",1) | K13: 1 | L13: 319000 | M13: 영보 | N13: PF-23032 (P30D 사각 튜브) 12CM | O13: POLYESTER | P13: 100 | Q13: 30D | R13: 135G | S13: 442T | T13: Single L | V13: WR | X13: 우븐 | Y13: TUBE | Z13: Ra_LV2 | AA13: GU_LV2 | AB13: 2L 구조(튜브) | AC13: (다운백 없음) | AD13: =AC13 -> (다운백 없음) | AE13: EU GOOSE 8020 | AF13: 184G | AG13: 중량 | AH13: 650 | AI13: 미드패딩 | AJ13: 미드 | AK13: 1008 | AL13: 321552000 | AM13: 35 | AN13: 7805500 | AO13: 174 | AP13: 41391680 | AQ13: 396 | AR13: 90643180 | AS13: =AQ13/AK13 -> 0.39285714
A14: =B14&I14 -> DWDJ9D046IVD | B14: DWDJ9D046 | C14: =MID(B14,3,5) -> DJ9D0 | D14: MAIN | E14: =MID($B14,2,1) -> W | F14: =MID($B14,3,2) -> DJ | G14: WINTER | H14: 여성 멜로즈 튜브 구스다운 경량 롱패딩 | I14: IVD | J14: =IF(B14=B13,"",1) -> 1 | K14: 1 | L14: 339000 | M14: 영보 | N14: PF-23032 (P30D 사각 튜브) 12CM | O14: POLYESTER | P14: 100 | Q14: 30D | R14: 135G | S14: 442T | T14: Single L | V14: WR | X14: 우븐 | Y14: TUBE | Z14: Ra_LV2 | AA14: GU_LV2 | AB14: 2L 구조(튜브) | AC14: (다운백 없음) | AD14: =AC14 -> (다운백 없음) | AE14: EU GOOSE 8020 | AF14: 180G | AG14: 중량 | AH14: 650 | AI14: 롱패딩 | AJ14: 롱 | AK14: 1109 | AL14: 375951000 | AM14: 79 | AN14: 18732980 | AO14: 467 | AP14: 115511586 | AQ14: 865 | AR14: 208753316 | AS14: =AQ14/AK14 -> 0.77998197
A15: =B15&I15 -> DWDJ9D046BKS | B15: DWDJ9D046 | C15: =MID(B15,3,5) -> DJ9D0 | D15: MAIN | E15: =MID($B15,2,1) -> W | F15: =MID($B15,3,2) -> DJ | G15: WINTER | H15: 여성 멜로즈 튜브 구스다운 경량 롱패딩 | I15: BKS | J15: =IF(B15=B14,"",1) | K15: 1 | L15: 339000 | M15: 영보 | N15: PF-23032 (P30D 사각 튜브) 12CM | O15: POLYESTER | P15: 100 | Q15: 30D | R15: 135G | S15: 442T | T15: Single L | V15: WR | X15: 우븐 | Y15: TUBE | Z15: Ra_LV2 | AA15: GU_LV2 | AB15: 2L 구조(튜브) | AC15: (다운백 없음) | AD15: =AC15 -> (다운백 없음) | AE15: EU GOOSE 8020 | AF15: 180G | AG15: 중량 | AH15: 650 | AI15: 롱패딩 | AJ15: 롱 | AK15: 1604 | AL15: 543756000 | AM15: 160 | AN15: 37991000 | AO15: 1178 | AP15: 289450323 | AQ15: 1568 | AR15: 381404023 | AS15: =AQ15/AK15 -> 0.97755611
A16: =B16&I16 -> DWDJ9F046IVS | B16: DWDJ9F046 | C16: =MID(B16,3,5) -> DJ9F0 | D16: MAIN | E16: =MID($B16,2,1) -> W | F16: =MID($B16,3,2) -> DJ | G16: WINTER | H16: 여성 올핀 구스다운 경량패딩 | I16: IVS | J16: =IF(B16=B15,"",1) -> 1 | K16: 1 | L16: 229000 | M16: 봄텍스 | N16: BOM-SB1368CA (JS1001 PU 뺀 VER.) | O16: POLYESTER | P16: 100 | Q16: 20D | R16: 45G | S16: 435T | T16: Single L | V16: WR | X16: 우븐 | Y16: PLAIN | Z16: Ra_LV1 | AA16: GU_LV4 | AB16: 4L 구조 | AC16: 20D | AD16: 400T | AE16: EU GOOSE 8020 | AF16: 120G | AG16: 중량 | AH16: 650 | AI16: 중량패딩 | AJ16: 크롭 | AK16: 997 | AL16: 228313000 | AM16: 8 | AN16: 1812000 | AO16: 437 | AP16: 97527770 | AQ16: 587 | AR16: 130725033 | AS16: =AQ16/AK16 -> 0.5887663
A17: =B17&I17 -> DWDJ9F046GRL | B17: DWDJ9F046 | C17: =MID(B17,3,5) -> DJ9F0 | D17: MAIN | E17: =MID($B17,2,1) -> W | F17: =MID($B17,3,2) -> DJ | G17: WINTER | H17: 여성 올핀 구스다운 경량패딩 | I17: GRL | J17: =IF(B17=B16,"",1) | K17: 1 | L17: 229000 | M17: 봄텍스 | N17: BOM-SB1368CA (JS1001 PU 뺀 VER.) | O17: POLYESTER | P17: 100 | Q17: 20D | R17: 45G | S17: 435T | T17: Single L | V17: WR | X17: 우븐 | Y17: PLAIN | Z17: Ra_LV1 | AA17: GU_LV4 | AB17: 4L 구조 | AC17: 20D | AD17: 400T | AE17: EU GOOSE 8020 | AF17: 120G | AG17: 중량 | AH17: 650 | AI17: 중량패딩 | AJ17: 크롭 | AK17: 998 | AL17: 228542000 | AM17: 15 | AN17: 3272400 | AO17: 300 | AP17: 65512505 | AQ17: 463 | AR17: 101911394 | AS17: =AQ17/AK17 -> 0.46392786
A18: =B18&I18 -> DWDJ9F046BKS | B18: DWDJ9F046 | C18: =MID(B18,3,5) -> DJ9F0 | D18: MAIN | E18: =MID($B18,2,1) -> W | F18: =MID($B18,3,2) -> DJ | G18: WINTER | H18: 여성 올핀 구스다운 경량패딩 | I18: BKS | J18: =IF(B18=B17,"",1) | K18: 1 | L18: 229000 | M18: 봄텍스 | N18: BOM-SB1368CA (JS1001 PU 뺀 VER.) | O18: POLYESTER | P18: 100 | Q18: 20D | R18: 45G | S18: 435T | T18: Single L | V18: WR | X18: 우븐 | Y18: PLAIN | Z18: Ra_LV1 | AA18: GU_LV4 | AB18: 4L 구조 | AC18: 20D | AD18: 400T | AE18: EU GOOSE 8020 | AF18: 120G | AG18: 중량 | AH18: 650 | AI18: 중량패딩 | AJ18: 크롭 | AK18: 1493 | AL18: 341897000 | AM18: 29 | AN18: 6545200 | AO18: 536 | AP18: 119889521 | AQ18: 768 | AR18: 170939520 | AS18: =AQ18/AK18 -> 0.51440054
A19: =B19&I19 -> DWDJ9E046COS | B19: DWDJ9E046 | C19: =MID(B19,3,5) -> DJ9E0 | D19: MAIN | E19: =MID($B19,2,1) -> W | F19: =MID($B19,3,2) -> DJ | G19: WINTER | H19: 여성 베르겐 고어윈드스토퍼 크롭 구스다운 숏패딩 | I19: COS | J19: =IF(B19=B18,"",1) -> 1 | K19: 1 | L19: 379000 | M19: GORE | N19: bnrSPL50NJ 2L | O19: POLYESTER | P19: 100 | Q19: 50D | R19: 102G | S19: 300T | T19: 2L | U19: 30mic | V19: WR | W19: GORE-TEX | X19: 우븐 | Y19: PLAIN | Z19: Ra_LV2 | AA19: GU_LV2 | AB19: 4L 구조 | AC19: 20D | AD19: 400T | AE19: EU GOOSE 8020 | AF19: 125G | AG19: 헤비 | AH19: 650 | AI19: 크롭패딩 | AJ19: 슈퍼크롭 | AK19: 770 | AL19: 291830000 | AM19: 0 | AN19: 0 | AO19: 13 | AP19: 4626416 | AQ19: 25 | AR19: 8189016 | AS19: =AQ19/AK19 -> 0.032467532
A20: =B20&I20 -> DWDJ9E046IVS | B20: DWDJ9E046 | C20: =MID(B20,3,5) -> DJ9E0 | D20: MAIN | E20: =MID($B20,2,1) -> W | F20: =MID($B20,3,2) -> DJ | G20: WINTER | H20: 여성 베르겐 고어윈드스토퍼 크롭 구스다운 숏패딩 | I20: IVS | J20: =IF(B20=B19,"",1) | K20: 1 | L20: 379000 | M20: GORE | N20: bnrSPL50NJ 2L | O20: POLYESTER | P20: 100 | Q20: 50D | R20: 102G | S20: 300T | T20: 2L | U20: 30mic | V20: WR | W20: GORE-TEX | X20: 우븐 | Y20: PLAIN | Z20: Ra_LV2 | AA20: GU_LV2 | AB20: 4L 구조 | AC20: 20D | AD20: 400T | AE20: EU GOOSE 8020 | AF20: 125G | AG20: 헤비 | AH20: 650 | AI20: 크롭패딩 | AJ20: 슈퍼크롭 | AK20: 950 | AL20: 360050000 | AM20: 12 | AN20: 4546000 | AO20: 47 | AP20: 17341854 | AQ20: 108 | AR20: 35888654 | AS20: =AQ20/AK20 -> 0.11368421
A21: =B21&I21 -> DWDJ9E046BKS | B21: DWDJ9E046 | C21: =MID(B21,3,5) -> DJ9E0 | D21: MAIN | E21: =MID($B21,2,1) -> W | F21: =MID($B21,3,2) -> DJ | G21: WINTER | H21: 여성 베르겐 고어윈드스토퍼 크롭 구스다운 숏패딩 | I21: BKS | J21: =IF(B21=B20,"",1) | K21: 1 | L21: 379000 | M21: GORE | N21: bnrSPL50NJ 2L | O21: POLYESTER | P21: 100 | Q21: 50D | R21: 102G | S21: 300T | T21: 2L | U21: 30mic | V21: WR | W21: GORE-TEX | X21: 우븐 | Y21: PLAIN | Z21: Ra_LV2 | AA21: GU_LV2 | AB21: 4L 구조 | AC21: 20D | AD21: 400T | AE21: EU GOOSE 8020 | AF21: 125G | AG21: 헤비 | AH21: 650 | AI21: 크롭패딩 | AJ21: 슈퍼크롭 | AK21: 1155 | AL21: 437745000 | AM21: 17 | AN21: 6417000 | AO21: 83 | AP21: 31154681 | AQ21: 227 | AR21: 74565901 | AS21: =AQ21/AK21 -> 0.1965368
A22: =B22&I22 -> DWDJ93046GRL | B22: DWDJ93046 | C22: =MID(B22,3,5) -> DJ930 | D22: MAIN | E22: =MID($B22,2,1) -> W | F22: =MID($B22,3,2) -> DJ | G22: WINTER | H22: 여성 올리브 RDS 다운 숏패딩 | I22: GRL | J22: =IF(B22=B21,"",1) -> 1 | K22: 1 | L22: 279000 | M22: FLOW TEX | N22: CJP-336 | O22: POLYESTER | P22: 100 | Q22: 30D | R22: 58G | S22: 322T | T22: 2L | U22: 7mic | V22: WR | X22: 우븐 | Y22: PLAIN | Z22: Ra_LV2 | AA22: GU_LV2 | AB22: 4L 구조 | AC22: 20D | AD22: 400T | AE22: EU DUCK 8020 | AF22: 180G | AG22: 헤비 | AH22: 650 | AI22: 크롭패딩 | AJ22: 세미크롭 | AK22: 5602 | AL22: 1562958000 | AM22: 371 | AN22: 102393107 | AO22: 1500 | AP22: 412705796 | AQ22: 3493 | AR22: 948034537 | AS22: =AQ22/AK22 -> 0.62352731
A23: =B23&I23 -> DWDJ93046CRS | B23: DWDJ93046 | C23: =MID(B23,3,5) -> DJ930 | D23: MAIN | E23: =MID($B23,2,1) -> W | F23: =MID($B23,3,2) -> DJ | G23: WINTER | H23: 여성 올리브 RDS 다운 숏패딩 | I23: CRS | J23: =IF(B23=B22,"",1) | K23: 1 | L23: 279000 | M23: FLOW TEX | N23: CJP-336 | O23: POLYESTER | P23: 100 | Q23: 30D | R23: 58G | S23: 322T | T23: 2L | U23: 7mic | V23: WR | X23: 우븐 | Y23: PLAIN | Z23: Ra_LV2 | AA23: GU_LV2 | AB23: 4L 구조 | AC23: 20D | AD23: 400T | AE23: EU DUCK 8020 | AF23: 180G | AG23: 헤비 | AH23: 650 | AI23: 크롭패딩 | AJ23: 세미크롭 | AK23: 10190 | AL23: 2843010000 | AM23: 483 | AN23: 133497021 | AO23: 2098 | AP23: 578317896 | AQ23: 4672 | AR23: 1270703725 | AS23: =AQ23/AK23 -> 0.45848871
A24: =B24&I24 -> DWDJ93046BRL | B24: DWDJ93046 | C24: =MID(B24,3,5) -> DJ930 | D24: MAIN | E24: =MID($B24,2,1) -> W | F24: =MID($B24,3,2) -> DJ | G24: WINTER | H24: 여성 올리브 RDS 다운 숏패딩 | I24: BRL | J24: =IF(B24=B23,"",1) | K24: 1 | L24: 279000 | M24: FLOW TEX | N24: CJP-336 | O24: POLYESTER | P24: 100 | Q24: 30D | R24: 58G | S24: 322T | T24: 2L | U24: 7mic | V24: WR | X24: 우븐 | Y24: PLAIN | Z24: Ra_LV2 | AA24: GU_LV2 | AB24: 4L 구조 | AC24: 20D | AD24: 400T | AE24: EU DUCK 8020 | AF24: 180G | AG24: 헤비 | AH24: 650 | AI24: 크롭패딩 | AJ24: 세미크롭 | AK24: 3042 | AL24: 848718000 | AM24: 231 | AN24: 63758268 | AO24: 1091 | AP24: 299292932 | AQ24: 2330 | AR24: 631287623 | AS24: =AQ24/AK24 -> 0.76594346
A25: =B25&I25 -> DWDJ93046LDS | B25: DWDJ93046 | C25: =MID(B25,3,5) -> DJ930 | D25: MAIN | E25: =MID($B25,2,1) -> W | F25: =MID($B25,3,2) -> DJ | G25: WINTER | H25: 여성 올리브 RDS 다운 숏패딩 | I25: LDS | J25: =IF(B25=B24,"",1) | K25: 1 | L25: 279000 | M25: FLOW TEX | N25: CJP-336 | O25: POLYESTER | P25: 100 | Q25: 30D | R25: 58G | S25: 322T | T25: 2L | U25: 7mic | V25: WR | X25: 우븐 | Y25: PLAIN | Z25: Ra_LV2 | AA25: GU_LV2 | AB25: 4L 구조 | AC25: 20D | AD25: 400T | AE25: EU DUCK 8020 | AF25: 180G | AG25: 헤비 | AH25: 650 | AI25: 크롭패딩 | AJ25: 세미크롭 | AK25: 2012 | AL25: 561348000 | AM25: 33 | AN25: 9168861 | AO25: 184 | AP25: 50610238 | AQ25: 416 | AR25: 113347710 | AS25: =AQ25/AK25 -> 0.20675944
A26: =B26&I26 -> DWDJ93046BKS | B26: DWDJ93046 | C26: =MID(B26,3,5) -> DJ930 | D26: MAIN | E26: =MID($B26,2,1) -> W | F26: =MID($B26,3,2) -> DJ | G26: WINTER | H26: 여성 올리브 RDS 다운 숏패딩 | I26: BKS | J26: =IF(B26=B25,"",1) | K26: 1 | L26: 279000 | M26: FLOW TEX | N26: CJP-336 | O26: POLYESTER | P26: 100 | Q26: 30D | R26: 58G | S26: 322T | T26: 2L | U26: 7mic | V26: WR | X26: 우븐 | Y26: PLAIN | Z26: Ra_LV2 | AA26: GU_LV2 | AB26: 4L 구조 | AC26: 20D | AD26: 400T | AE26: EU DUCK 8020 | AF26: 180G | AG26: 헤비 | AH26: 650 | AI26: 크롭패딩 | AJ26: 세미크롭 | AK26: 10619 | AL26: 2962701000 | AM26: 896 | AN26: 247662771 | AO26: 3376 | AP26: 931994651 | AQ26: 7985 | AR26: 2173706668 | AS26: =AQ26/AK26 -> 0.75195404
A27: =B27&I27 -> DWDJ93046BKN | B27: DWDJ93046 | C27: =MID(B27,3,5) -> DJ930 | D27: MAIN | E27: =MID($B27,2,1) -> W | F27: =MID($B27,3,2) -> DJ | G27: WINTER | H27: 여성 올리브 RDS 다운 숏패딩 | I27: BKN | J27: =IF(B27=B26,"",1) | K27: 1 | L27: 279000 | M27: SPM | N27: MC-233 (1) | O27: NYLON | P27: 100 | Q27: 40D | R27: 55G | S27: 279T | T27: Single L | V27: WR | X27: 우븐 | Y27: PLAIN | Z27: Ra_LV1 | AA27: GU_LV5 | AB27: 4L 구조 | AC27: 20D | AD27: 400T | AE27: EU DUCK 8020 | AF27: 180G | AG27: 헤비 | AH27: 650 | AI27: 크롭패딩 | AJ27: 세미크롭 | AK27: 2033 | AL27: 567207000 | AM27: 251 | AN27: 68813216 | AO27: 1024 | AP27: 281593831 | AQ27: 1849 | AR27: 502215616 | AS27: =AQ27/AK27 -> 0.90949336
A28: =B28&I28 -> DWDJ93046BRN | B28: DWDJ93046 | C28: =MID(B28,3,5) -> DJ930 | D28: SPOT | E28: =MID($B28,2,1) -> W | F28: =MID($B28,3,2) -> DJ | G28: WINTER | H28: 여성 올리브 RDS 다운 숏패딩 | I28: BRN | J28: =IF(B28=B27,"",1) | K28: 1 | L28: 279000 | M28: C&A | N28: CAC-6912 2T | O28: NYLON | P28: 100 | Q28: 40D | R28: 55G | S28: 290T | T28: Single L | V28: CIRE | X28: 우븐 | Y28: PLAIN | Z28: Ra_LV1 | AA28: GU_LV5 | AB28: 4L 구조 | AC28: 20D | AD28: 400T | AE28: EU DUCK 8020 | AF28: 180G | AG28: 헤비 | AH28: 650 | AI28: 크롭패딩 | AJ28: 세미크롭 | AK28: 1560 | AL28: 435240000 | AM28: 135 | AN28: 37191052 | AO28: 543 | AP28: 149071994 | AQ28: 1114 | AR28: 301186611 | AS28: =AQ28/AK28 -> 0.71410256
A29: =B29&I29 -> DWDJ93046BDS | B29: DWDJ93046 | C29: =MID(B29,3,5) -> DJ930 | D29: SPOT | E29: =MID($B29,2,1) -> W | F29: =MID($B29,3,2) -> DJ | G29: WINTER | H29: 여성 올리브 RDS 다운 숏패딩 | I29: BDS | J29: =IF(B29=B28,"",1) | K29: 1 | L29: 279000 | M29: FLOW TEX | N29: CJP-336 | O29: POLYESTER | P29: 100 | Q29: 30D | R29: 58G | S29: 322T | T29: 2L | U29: 7mic | V29: WR | X29: 우븐 | Y29: PLAIN | Z29: Ra_LV2 | AA29: GU_LV2 | AB29: 4L 구조 | AC29: 20D | AD29: 400T | AE29: EU DUCK 8020 | AF29: 180G | AG29: 헤비 | AH29: 650 | AI29: 크롭패딩 | AJ29: 세미크롭 | AK29: 1452 | AL29: 405108000 | AM29: 26 | AN29: 7166809 | AO29: 35 | AP29: 9647809 | AQ29: 273 | AR29: 73447486 | AS29: =AQ29/AK29 -> 0.18801653
A30: =B30&I30 -> DWDJ97046BKS | B30: DWDJ97046 | C30: =MID(B30,3,5) -> DJ970 | D30: MAIN | E30: =MID($B30,2,1) -> W | F30: =MID($B30,3,2) -> DJ | G30: WINTER | H30: 여성 올리브 크롭 RDS 다운 숏패딩 | I30: BKS | J30: =IF(B30=B29,"",1) -> 1 | K30: 1 | L30: 279000 | M30: FLOW TEX | N30: CJP-336 | O30: POLYESTER | P30: 100 | Q30: 30D | R30: 58G | S30: 322T | T30: 2L | U30: 7mic | V30: WR | X30: 우븐 | Y30: PLAIN | Z30: Ra_LV2 | AA30: GU_LV2 | AB30: 4L 구조 | AC30: 20D | AD30: 400T | AE30: EU DUCK 8020 | AF30: 155G | AG30: 헤비 | AH30: 650 | AI30: 크롭패딩 | AJ30: 슈퍼크롭 | AK30: 2849 | AL30: 794871000 | AM30: 250 | AN30: 68883850 | AO30: 1150 | AP30: 317272889 | AQ30: 1962 | AR30: 535314075 | AS30: =AQ30/AK30 -> 0.68866269
A31: =B31&I31 -> DWDJ97046CRS | B31: DWDJ97046 | C31: =MID(B31,3,5) -> DJ970 | D31: MAIN | E31: =MID($B31,2,1) -> W | F31: =MID($B31,3,2) -> DJ | G31: WINTER | H31: 여성 올리브 크롭 RDS 다운 숏패딩 | I31: CRS | J31: =IF(B31=B30,"",1) | K31: 1 | L31: 279000 | M31: FLOW TEX | N31: CJP-336 | O31: POLYESTER | P31: 100 | Q31: 30D | R31: 58G | S31: 322T | T31: 2L | U31: 7mic | V31: WR | X31: 우븐 | Y31: PLAIN | Z31: Ra_LV2 | AA31: GU_LV2 | AB31: 4L 구조 | AC31: 20D | AD31: 400T | AE31: EU DUCK 8020 | AF31: 155G | AG31: 헤비 | AH31: 650 | AI31: 크롭패딩 | AJ31: 슈퍼크롭 | AK31: 1628 | AL31: 454212000 | AM31: 132 | AN31: 36484310 | AO31: 606 | AP31: 167095340 | AQ31: 1078 | AR31: 294145910 | AS31: =AQ31/AK31 -> 0.66216216
A32: =B32&I32 -> DWDJ97046BRD | B32: DWDJ97046 | C32: =MID(B32,3,5) -> DJ970 | D32: MAIN | E32: =MID($B32,2,1) -> W | F32: =MID($B32,3,2) -> DJ | G32: WINTER | H32: 여성 올리브 크롭 RDS 다운 숏패딩 | I32: BRD | J32: =IF(B32=B31,"",1) | K32: 1 | L32: 279000 | M32: FLOW TEX | N32: CJP-336 | O32: POLYESTER | P32: 100 | Q32: 30D | R32: 58G | S32: 322T | T32: 2L | U32: 7mic | V32: WR | X32: 우븐 | Y32: PLAIN | Z32: Ra_LV2 | AA32: GU_LV2 | AB32: 4L 구조 | AC32: 20D | AD32: 400T | AE32: EU DUCK 8020 | AF32: 155G | AG32: 헤비 | AH32: 650 | AI32: 크롭패딩 | AJ32: 슈퍼크롭 | AK32: 1628 | AL32: 454212000 | AM32: 137 | AN32: 37444060 | AO32: 668 | AP32: 182584560 | AQ32: 1121 | AR32: 303511309 | AS32: =AQ32/AK32 -> 0.68857494
A33: =B33&I33 -> DWDJ97046PKS | B33: DWDJ97046 | C33: =MID(B33,3,5) -> DJ970 | D33: MAIN | E33: =MID($B33,2,1) -> W | F33: =MID($B33,3,2) -> DJ | G33: WINTER | H33: 여성 올리브 크롭 RDS 다운 숏패딩 | I33: PKS | J33: =IF(B33=B32,"",1) | K33: 1 | L33: 279000 | M33: FLOW TEX | N33: CJP-336 | O33: POLYESTER | P33: 100 | Q33: 30D | R33: 58G | S33: 322T | T33: 2L | U33: 7mic | V33: WR | X33: 우븐 | Y33: PLAIN | Z33: Ra_LV2 | AA33: GU_LV2 | AB33: 4L 구조 | AC33: 20D | AD33: 400T | AE33: EU DUCK 8020 | AF33: 155G | AG33: 헤비 | AH33: 650 | AI33: 크롭패딩 | AJ33: 슈퍼크롭 | AK33: 1012 | AL33: 282348000 | AM33: 11 | AN33: 3064001 | AO33: 71 | AP33: 19328011 | AQ33: 168 | AR33: 45636411 | AS33: =AQ33/AK33 -> 0.16600791
A34: =B34&I34 -> DWDJ9G046BGL | B34: DWDJ9G046 | C34: =MID(B34,3,5) -> DJ9G0 | D34: MAIN | E34: =MID($B34,2,1) -> W | F34: =MID($B34,3,2) -> DJ | G34: WINTER | H34: 여성 헤이니(HAYNEY) 다운 숏패딩 | I34: BGL | J34: =IF(B34=B33,"",1) -> 1 | K34: 1 | L34: 279000 | M34: 봄텍스 | N34: BOM-JS1001(SB1368SPCA) | O34: POLYESTER | P34: 100 | Q34: 20D | R34: 52G | S34: 357T | T34: Single L | V34: WR | X34: 우븐 | Y34: PLAIN | Z34: Ra_LV1 | AA34: GU_LV4 | AB34: 4L 구조 | AC34: 20D | AD34: 400T | AE34: EU DUCK 8020 | AF34: 150G | AG34: 헤비 | AH34: 650 | AI34: 크롭패딩 | AJ34: 슈퍼크롭 | AK34: 2014 | AL34: 561906000 | AM34: 24 | AN34: 6498830 | AO34: 104 | AP34: 28289461 | AQ34: 233 | AR34: 62865737 | AS34: =AQ34/AK34 -> 0.11569017
A35: =B35&I35 -> DWDJ9G046BKN | B35: DWDJ9G046 | C35: =MID(B35,3,5) -> DJ9G0 | D35: MAIN | E35: =MID($B35,2,1) -> W | F35: =MID($B35,3,2) -> DJ | G35: WINTER | H35: 여성 헤이니(HAYNEY) 다운 숏패딩 | I35: BKN | J35: =IF(B35=B34,"",1) | K35: 1 | L35: 279000 | M35: 26STORY | N35: 26S-BELLINA-1003 | O35: POLYESTER | P35: 100 | Q35: 50D | R35: 160G | S35: 290T | T35: 2L | X35: 우븐 | Y35: PLAIN | Z35: Ra_LV1 | AA35: GU_LV4 | AB35: 4L 구조 | AC35: 20D | AD35: 400T | AE35: EU DUCK 8020 | AF35: 145G | AG35: 헤비 | AH35: 650 | AI35: 크롭패딩 | AJ35: 슈퍼크롭 | AK35: 4043 | AL35: 1127997000 | AM35: 310 | AN35: 85017738 | AO35: 1777 | AP35: 487575184 | AQ35: 3880 | AR35: 1047164309 | AS35: =AQ35/AK35 -> 0.9596834
A36: =B36&I36 -> DWDJ9G046CRS | B36: DWDJ9G046 | C36: =MID(B36,3,5) -> DJ9G0 | D36: MAIN | E36: =MID($B36,2,1) -> W | F36: =MID($B36,3,2) -> DJ | G36: WINTER | H36: 여성 헤이니(HAYNEY) 다운 숏패딩 | I36: CRS | J36: =IF(B36=B35,"",1) | K36: 1 | L36: 279000 | M36: 봄텍스 | N36: BOM-JS1001(SB1368SPCA) | O36: POLYESTER | P36: 100 | Q36: 20D | R36: 52G | S36: 357T | T36: Single L | V36: WR | X36: 우븐 | Y36: PLAIN | Z36: Ra_LV1 | AA36: GU_LV4 | AB36: 4L 구조 | AC36: 20D | AD36: 400T | AE36: EU DUCK 8020 | AF36: 150G | AG36: 헤비 | AH36: 650 | AI36: 크롭패딩 | AJ36: 슈퍼크롭 | AK36: 2500 | AL36: 697500000 | AM36: 112 | AN36: 30821814 | AO36: 562 | AP36: 154871414 | AQ36: 1116 | AR36: 303493686 | AS36: =AQ36/AK36 -> 0.4464
A37: =B37&I37 -> DWDJ9G046BKS | B37: DWDJ9G046 | C37: =MID(B37,3,5) -> DJ9G0 | D37: MAIN | E37: =MID($B37,2,1) -> W | F37: =MID($B37,3,2) -> DJ | G37: WINTER | H37: 여성 헤이니(HAYNEY) 다운 숏패딩 | I37: BKS | J37: =IF(B37=B36,"",1) | K37: 1 | L37: 279000 | M37: 봄텍스 | N37: BOM-JS1001(SB1368SPCA) | O37: POLYESTER | P37: 100 | Q37: 20D | R37: 52G | S37: 357T | T37: Single L | V37: WR | X37: 우븐 | Y37: PLAIN | Z37: Ra_LV1 | AA37: GU_LV4 | AB37: 4L 구조 | AC37: 20D | AD37: 400T | AE37: EU DUCK 8020 | AF37: 150G | AG37: 헤비 | AH37: 650 | AI37: 크롭패딩 | AJ37: 슈퍼크롭 | AK37: 4056 | AL37: 1131624000 | AM37: 332 | AN37: 91539167 | AO37: 1373 | AP37: 378766343 | AQ37: 2588 | AR37: 705845653 | AS37: =AQ37/AK37 -> 0.63806706
A38: =B38&I38 -> DWDJ9G046OLN | B38: DWDJ9G046 | C38: =MID(B38,3,5) -> DJ9G0 | D38: SPOT | E38: =MID($B38,2,1) -> W | F38: =MID($B38,3,2) -> DJ | G38: WINTER | H38: 여성 헤이니(HAYNEY) 다운 숏패딩 | I38: OLN | J38: =IF(B38=B37,"",1) | K38: 1 | L38: 279000 | M38: 26STORY | N38: 26S-BELLINA-1003 | O38: POLYESTER | P38: 100 | Q38: 50D | R38: 160G | S38: 290T | T38: 2L | X38: 우븐 | Y38: PLAIN | Z38: Ra_LV1 | AA38: GU_LV4 | AB38: 4L 구조 | AC38: 20D | AD38: 400T | AE38: EU DUCK 8020 | AF38: 145G | AG38: 헤비 | AH38: 650 | AI38: 크롭패딩 | AJ38: 슈퍼크롭 | AK38: 1590 | AL38: 443610000 | AM38: 119 | AN38: 32707225 | AO38: 641 | AP38: 175209912 | AQ38: 1039 | AR38: 282208407 | AS38: =AQ38/AK38 -> 0.65345912
A39: =B39&I39 -> DWDJ94046BKN | B39: DWDJ94046 | C39: =MID(B39,3,5) -> DJ940 | D39: MAIN | E39: =MID($B39,2,1) -> W | F39: =MID($B39,3,2) -> DJ | G39: WINTER | H39: 여성 올리아 RDS 다운 숏패딩 | I39: BKN | J39: =IF(B39=B38,"",1) -> 1 | K39: 1 | L39: 279000 | M39: SPM | N39: MC-233 | O39: NYLON | P39: 100 | Q39: 40D | R39: 55G | S39: 279T | T39: Single L | V39: WR | X39: 우븐 | Y39: PLAIN | Z39: Ra_LV1 | AA39: GU_LV5 | AB39: 4L 구조 | AC39: 20D | AD39: 400T | AE39: EU DUCK 8020 | AF39: 175G | AG39: 헤비 | AH39: 650 | AI39: 크롭패딩 | AJ39: 크롭 | AK39: 1191 | AL39: 332289000 | AM39: 134 | AN39: 36950074 | AO39: 834 | AP39: 229274570 | AQ39: 1053 | AR39: 287914007 | AS39: =AQ39/AK39 -> 0.88413098
A40: =B40&I40 -> DWDJ94046CRS | B40: DWDJ94046 | C40: =MID(B40,3,5) -> DJ940 | D40: MAIN | E40: =MID($B40,2,1) -> W | F40: =MID($B40,3,2) -> DJ | G40: WINTER | H40: 여성 올리아 RDS 다운 숏패딩 | I40: CRS | J40: =IF(B40=B39,"",1) | K40: 1 | L40: 279000 | M40: FLOW TEX | N40: CJP-336 | O40: POLYESTER | P40: 100 | Q40: 30D | R40: 58G | S40: 322T | T40: 2L | U40: 7mic | V40: WR | X40: 우븐 | Y40: PLAIN | Z40: Ra_LV2 | AA40: GU_LV2 | AB40: 4L 구조 | AC40: 20D | AD40: 400T | AE40: EU DUCK 8020 | AF40: 180G | AG40: 헤비 | AH40: 650 | AI40: 크롭패딩 | AJ40: 크롭 | AK40: 4050 | AL40: 1129950000 | AM40: 506 | AN40: 139634992 | AO40: 2383 | AP40: 657434225 | AQ40: 3735 | AR40: 1022119185 | AS40: =AQ40/AK40 -> 0.92222222
...

Sheet DJ 2025 FW
B1: 2025FW 다운 | AK1: =AK3/'DJ 2024 FW'!AK3-1 -> -0.040643088 | AL1: =AL3/'DJ 2024 FW'!AL3-1 -> -0.017044975 | AM1: =AM3/'DJ 2024 FW'!AM3-1 -> -0.11867029 | AN1: =AN3/'DJ 2024 FW'!AN3-1 -> -0.0014128931 | AO1: =AO3/'DJ 2024 FW'!AO3-1 -> -0.21270698 | AP1: =AP3/'DJ 2024 FW'!AP3-1 -> -0.13456743 | AQ1: =AQ3/'DJ 2024 FW'!AQ3-1 -> -0.088121009 | AR1: =AR3/'DJ 2024 FW'!AR3-1 -> -0.02541798 | AS1: =AS3-'DJ 2024 FW'!AS3 -> -0.029388614
B2: ▶제품 기준 정보 | M2: ▶소재 스팩 정보 | X2: ▶소재 외관 정보 | AB2: ▶다운백 정보 | AE2: ▶충전재 정보 | AI2: ▶디자인 정보 | AK2: ▶발주, 판매 정보 (251207일자)
D3: CN 이관 제외 | J3: =SUBTOTAL(9,$J$5:$J$999) -> 80 | K3: =SUBTOTAL(9,$K$5:$K$999) -> 259 | Z3: Ra값 (Roughness Average) | AA3: GU값 (Gloss Units) | AK3: =SUBTOTAL(9,AK5:AK999) -> 636281 | AL3: =SUBTOTAL(9,AL5:AL999) -> 209443892000 | AM3: =SUBTOTAL(9,AM5:AM999) -> 30197 | AN3: =SUBTOTAL(9,AN5:AN999) -> 9881533088 | AO3: =SUBTOTAL(9,AO5:AO999) -> 162750 | AP3: =SUBTOTAL(9,AP5:AP999) -> 46804354350 | AQ3: =SUBTOTAL(9,AQ5:AQ999) -> 359148.1 | AR3: =SUBTOTAL(9,AR5:AR999) -> 1.0664607e+11 | AS3: =AQ3/AK3 -> 0.56444888
B4: 품번 (9자리) | C4: 품번 (5자리) | D4: 발주 구분 | E4: 성별 코드 | F4: 아이템코드 | G4: 시즌 | H4: 제품명 | I4: 컬러코드 | J4: 스타일수 | K4: 컬러수 | L4: 예상TAG가 | M4: 소재처 | N4: 소재명 | O4: 소재 혼용율 | P4: 소재 혼용율% | Q4: 원사 데니아(D) | R4: 소재 중량(G) | S4: 소재 밀도(T) | T4: 레이어(필름) | U4: 레이어(필름) 두께 | V4: 소재 후가공 | W4: 소재 TAG | X4: 소재 구분 | Y4: 소재 조직 | Z4: 소재 텍스쳐(Ra) LEVEL | AA4: 소재 광택(GU) LEVEL | AB4: 다운백 구조 | AC4: 다운백 데니아(D) | AD4: 다운백 밀도(T) | AE4: 충전재 사종 | AF4: 충전재양(G) | AG4: 중량 구분 | AH4: 필파워 | AI4: 디자인 형태 | AJ4: 기장 | AK4: 발주 수량 | AL4: 발주 금액 | AM4: 주간 판매 수량 | AN4: 주간 판매 금액 | AO4: 누계 판매 수량 | AP4: 누계 판매 금액 | AQ4: 마감 판매수량 | AR4: 마감 판매금액 | AS4: 마감 판매율
A5: =B5&I5 -> DWDJ9M056GRL | B5: DWDJ9M056 | C5: =MID(B5,3,5) -> DJ9M0 | D5: MAIN | E5: =MID($B5,2,1) -> W | F5: =MID($B5,3,2) -> DJ | G5: WINTER | H5: 여성 올버트 뉴퀼팅 구스다운 경량패딩 | I5: GRL | J5: 1 | K5: 1 | L5: 279000 | M5: BOMTEX | N5: BOM-SB4129CC | O5: NYLON | P5: 100 | Q5: 10D | R5: 28G | S5: 470T | T5: Single L | V5: WR | X5: 우븐 | Y5: RIPSTOP | Z5: Ra_LV2 | AA5: GU_LV4 | AB5: 4L 구조 | AC5: 20D | AD5: 400T | AE5: EU GOOSE 8020 | AF5: 110G | AG5: 경량 | AH5: 650 | AI5: 경량패딩 | AJ5: 크롭 | AK5: =997+1200 -> 2197 | AL5: =AK5*L5 -> 612963000 | AM5: -1 | AN5: -464470 | AO5: 921 | AP5: 244285631 | AQ5: =AK5*AS5 -> 1977.3 | AR5: =(AL5*AS5)*0.92 -> 507533364 | AS5: 0.9
